2017-11-12 12:41:09,916 DEBUG org.apache.hadoop.yarn.server.resourcemanager.scheduler.capacity.CapacityScheduler: nodeUpdate: hadoop-worker02:35444 clusterResources: <memory:24576, vCores:24>
2017-11-12 12:41:09,917 DEBUG org.apache.hadoop.yarn.server.resourcemanager.scheduler.capacity.CapacityScheduler: Node being looked for scheduling hadoop-worker02:35444 availableResource: <memory:8192, vCores:8>
2017-11-12 12:41:09,917 DEBUG org.apache.hadoop.yarn.server.resourcemanager.scheduler.capacity.CapacityScheduler: Trying to schedule on node: hadoop-worker02, available: <memory:8192, vCores:8>
2017-11-12 12:41:09,917 DEBUG org.apache.hadoop.yarn.server.resourcemanager.scheduler.capacity.ParentQueue: Skip this queue=root, because it doesn't need more resource, schedulingMode=RESPECT_PARTITION_EXCLUSIVITY node-partition=
2017-11-12 12:41:09,928 DEBUG org.apache.hadoop.yarn.server.resourcemanager.scheduler.capacity.CapacityScheduler: nodeUpdate: hadoop-worker01:41792 clusterResources: <memory:24576, vCores:24>
2017-11-12 12:41:09,928 DEBUG org.apache.hadoop.yarn.server.resourcemanager.scheduler.capacity.CapacityScheduler: Node being looked for scheduling hadoop-worker01:41792 availableResource: <memory:8192, vCores:8>
2017-11-12 12:41:09,928 DEBUG org.apache.hadoop.yarn.server.resourcemanager.scheduler.capacity.CapacityScheduler: Trying to schedule on node: hadoop-worker01, available: <memory:8192, vCores:8>
2017-11-12 12:41:09,929 DEBUG org.apache.hadoop.yarn.server.resourcemanager.scheduler.capacity.ParentQueue: Skip this queue=root, because it doesn't need more resource, schedulingMode=RESPECT_PARTITION_EXCLUSIVITY node-partition=
2017-11-12 12:41:10,425 DEBUG org.apache.hadoop.yarn.server.resourcemanager.scheduler.capacity.CapacityScheduler: nodeUpdate: hadoop-worker03:34047 clusterResources: <memory:24576, vCores:24>
2017-11-12 12:41:10,425 DEBUG org.apache.hadoop.yarn.server.resourcemanager.scheduler.capacity.CapacityScheduler: Node being looked for scheduling hadoop-worker03:34047 availableResource: <memory:8192, vCores:8>
2017-11-12 12:41:10,425 DEBUG org.apache.hadoop.yarn.server.resourcemanager.scheduler.capacity.CapacityScheduler: Trying to schedule on node: hadoop-worker03, available: <memory:8192, vCores:8>
2017-11-12 12:41:10,425 DEBUG org.apache.hadoop.yarn.server.resourcemanager.scheduler.capacity.ParentQueue: Skip this queue=root, because it doesn't need more resource, schedulingMode=RESPECT_PARTITION_EXCLUSIVITY node-partition=
2017-11-12 12:41:10,917 DEBUG org.apache.hadoop.yarn.server.resourcemanager.scheduler.capacity.CapacityScheduler: nodeUpdate: hadoop-worker02:35444 clusterResources: <memory:24576, vCores:24>
2017-11-12 12:41:10,917 DEBUG org.apache.hadoop.yarn.server.resourcemanager.scheduler.capacity.CapacityScheduler: Node being looked for scheduling hadoop-worker02:35444 availableResource: <memory:8192, vCores:8>
2017-11-12 12:41:10,917 DEBUG org.apache.hadoop.yarn.server.resourcemanager.scheduler.capacity.CapacityScheduler: Trying to schedule on node: hadoop-worker02, available: <memory:8192, vCores:8>
2017-11-12 12:41:10,917 DEBUG org.apache.hadoop.yarn.server.resourcemanager.scheduler.capacity.ParentQueue: Skip this queue=root, because it doesn't need more resource, schedulingMode=RESPECT_PARTITION_EXCLUSIVITY node-partition=
2017-11-12 12:41:10,930 DEBUG org.apache.hadoop.yarn.server.resourcemanager.scheduler.capacity.CapacityScheduler: nodeUpdate: hadoop-worker01:41792 clusterResources: <memory:24576, vCores:24>
2017-11-12 12:41:10,930 DEBUG org.apache.hadoop.yarn.server.resourcemanager.scheduler.capacity.CapacityScheduler: Node being looked for scheduling hadoop-worker01:41792 availableResource: <memory:8192, vCores:8>
2017-11-12 12:41:10,930 DEBUG org.apache.hadoop.yarn.server.resourcemanager.scheduler.capacity.CapacityScheduler: Trying to schedule on node: hadoop-worker01, available: <memory:8192, vCores:8>
2017-11-12 12:41:10,930 DEBUG org.apache.hadoop.yarn.server.resourcemanager.scheduler.capacity.ParentQueue: Skip this queue=root, because it doesn't need more resource, schedulingMode=RESPECT_PARTITION_EXCLUSIVITY node-partition=
2017-11-12 12:41:11,427 DEBUG org.apache.hadoop.yarn.server.resourcemanager.scheduler.capacity.CapacityScheduler: nodeUpdate: hadoop-worker03:34047 clusterResources: <memory:24576, vCores:24>
2017-11-12 12:41:11,427 DEBUG org.apache.hadoop.yarn.server.resourcemanager.scheduler.capacity.CapacityScheduler: Node being looked for scheduling hadoop-worker03:34047 availableResource: <memory:8192, vCores:8>
2017-11-12 12:41:11,427 DEBUG org.apache.hadoop.yarn.server.resourcemanager.scheduler.capacity.CapacityScheduler: Trying to schedule on node: hadoop-worker03, available: <memory:8192, vCores:8>
2017-11-12 12:41:11,427 DEBUG org.apache.hadoop.yarn.server.resourcemanager.scheduler.capacity.ParentQueue: Skip this queue=root, because it doesn't need more resource, schedulingMode=RESPECT_PARTITION_EXCLUSIVITY node-partition=
2017-11-12 12:41:11,919 DEBUG org.apache.hadoop.yarn.server.resourcemanager.scheduler.capacity.CapacityScheduler: nodeUpdate: hadoop-worker02:35444 clusterResources: <memory:24576, vCores:24>
2017-11-12 12:41:11,919 DEBUG org.apache.hadoop.yarn.server.resourcemanager.scheduler.capacity.CapacityScheduler: Node being looked for scheduling hadoop-worker02:35444 availableResource: <memory:8192, vCores:8>
2017-11-12 12:41:11,919 DEBUG org.apache.hadoop.yarn.server.resourcemanager.scheduler.capacity.CapacityScheduler: Trying to schedule on node: hadoop-worker02, available: <memory:8192, vCores:8>
2017-11-12 12:41:11,919 DEBUG org.apache.hadoop.yarn.server.resourcemanager.scheduler.capacity.ParentQueue: Skip this queue=root, because it doesn't need more resource, schedulingMode=RESPECT_PARTITION_EXCLUSIVITY node-partition=
2017-11-12 12:41:11,932 DEBUG org.apache.hadoop.yarn.server.resourcemanager.scheduler.capacity.CapacityScheduler: nodeUpdate: hadoop-worker01:41792 clusterResources: <memory:24576, vCores:24>
2017-11-12 12:41:11,932 DEBUG org.apache.hadoop.yarn.server.resourcemanager.scheduler.capacity.CapacityScheduler: Node being looked for scheduling hadoop-worker01:41792 availableResource: <memory:8192, vCores:8>
2017-11-12 12:41:11,932 DEBUG org.apache.hadoop.yarn.server.resourcemanager.scheduler.capacity.CapacityScheduler: Trying to schedule on node: hadoop-worker01, available: <memory:8192, vCores:8>
2017-11-12 12:41:11,932 DEBUG org.apache.hadoop.yarn.server.resourcemanager.scheduler.capacity.ParentQueue: Skip this queue=root, because it doesn't need more resource, schedulingMode=RESPECT_PARTITION_EXCLUSIVITY node-partition=
2017-11-12 12:41:12,428 DEBUG org.apache.hadoop.yarn.server.resourcemanager.scheduler.capacity.CapacityScheduler: nodeUpdate: hadoop-worker03:34047 clusterResources: <memory:24576, vCores:24>
2017-11-12 12:41:12,428 DEBUG org.apache.hadoop.yarn.server.resourcemanager.scheduler.capacity.CapacityScheduler: Node being looked for scheduling hadoop-worker03:34047 availableResource: <memory:8192, vCores:8>
2017-11-12 12:41:12,428 DEBUG org.apache.hadoop.yarn.server.resourcemanager.scheduler.capacity.CapacityScheduler: Trying to schedule on node: hadoop-worker03, available: <memory:8192, vCores:8>
2017-11-12 12:41:12,428 DEBUG org.apache.hadoop.yarn.server.resourcemanager.scheduler.capacity.ParentQueue: Skip this queue=root, because it doesn't need more resource, schedulingMode=RESPECT_PARTITION_EXCLUSIVITY node-partition=
2017-11-12 12:41:12,920 DEBUG org.apache.hadoop.yarn.server.resourcemanager.scheduler.capacity.CapacityScheduler: nodeUpdate: hadoop-worker02:35444 clusterResources: <memory:24576, vCores:24>
2017-11-12 12:41:12,920 DEBUG org.apache.hadoop.yarn.server.resourcemanager.scheduler.capacity.CapacityScheduler: Node being looked for scheduling hadoop-worker02:35444 availableResource: <memory:8192, vCores:8>
2017-11-12 12:41:12,920 DEBUG org.apache.hadoop.yarn.server.resourcemanager.scheduler.capacity.CapacityScheduler: Trying to schedule on node: hadoop-worker02, available: <memory:8192, vCores:8>
2017-11-12 12:41:12,920 DEBUG org.apache.hadoop.yarn.server.resourcemanager.scheduler.capacity.ParentQueue: Skip this queue=root, because it doesn't need more resource, schedulingMode=RESPECT_PARTITION_EXCLUSIVITY node-partition=
2017-11-12 12:41:12,933 DEBUG org.apache.hadoop.yarn.server.resourcemanager.scheduler.capacity.CapacityScheduler: nodeUpdate: hadoop-worker01:41792 clusterResources: <memory:24576, vCores:24>
2017-11-12 12:41:12,933 DEBUG org.apache.hadoop.yarn.server.resourcemanager.scheduler.capacity.CapacityScheduler: Node being looked for scheduling hadoop-worker01:41792 availableResource: <memory:8192, vCores:8>
2017-11-12 12:41:12,933 DEBUG org.apache.hadoop.yarn.server.resourcemanager.scheduler.capacity.CapacityScheduler: Trying to schedule on node: hadoop-worker01, available: <memory:8192, vCores:8>
2017-11-12 12:41:12,933 DEBUG org.apache.hadoop.yarn.server.resourcemanager.scheduler.capacity.ParentQueue: Skip this queue=root, because it doesn't need more resource, schedulingMode=RESPECT_PARTITION_EXCLUSIVITY node-partition=
2017-11-12 12:41:13,429 DEBUG org.apache.hadoop.yarn.server.resourcemanager.scheduler.capacity.CapacityScheduler: nodeUpdate: hadoop-worker03:34047 clusterResources: <memory:24576, vCores:24>
2017-11-12 12:41:13,430 DEBUG org.apache.hadoop.yarn.server.resourcemanager.scheduler.capacity.CapacityScheduler: Node being looked for scheduling hadoop-worker03:34047 availableResource: <memory:8192, vCores:8>
2017-11-12 12:41:13,430 DEBUG org.apache.hadoop.yarn.server.resourcemanager.scheduler.capacity.CapacityScheduler: Trying to schedule on node: hadoop-worker03, available: <memory:8192, vCores:8>
2017-11-12 12:41:13,430 DEBUG org.apache.hadoop.yarn.server.resourcemanager.scheduler.capacity.ParentQueue: Skip this queue=root, because it doesn't need more resource, schedulingMode=RESPECT_PARTITION_EXCLUSIVITY node-partition=
2017-11-12 12:41:13,921 DEBUG org.apache.hadoop.yarn.server.resourcemanager.scheduler.capacity.CapacityScheduler: nodeUpdate: hadoop-worker02:35444 clusterResources: <memory:24576, vCores:24>
2017-11-12 12:41:13,921 DEBUG org.apache.hadoop.yarn.server.resourcemanager.scheduler.capacity.CapacityScheduler: Node being looked for scheduling hadoop-worker02:35444 availableResource: <memory:8192, vCores:8>
2017-11-12 12:41:13,921 DEBUG org.apache.hadoop.yarn.server.resourcemanager.scheduler.capacity.CapacityScheduler: Trying to schedule on node: hadoop-worker02, available: <memory:8192, vCores:8>
2017-11-12 12:41:13,921 DEBUG org.apache.hadoop.yarn.server.resourcemanager.scheduler.capacity.ParentQueue: Skip this queue=root, because it doesn't need more resource, schedulingMode=RESPECT_PARTITION_EXCLUSIVITY node-partition=
2017-11-12 12:41:13,935 DEBUG org.apache.hadoop.yarn.server.resourcemanager.scheduler.capacity.CapacityScheduler: nodeUpdate: hadoop-worker01:41792 clusterResources: <memory:24576, vCores:24>
2017-11-12 12:41:13,935 DEBUG org.apache.hadoop.yarn.server.resourcemanager.scheduler.capacity.CapacityScheduler: Node being looked for scheduling hadoop-worker01:41792 availableResource: <memory:8192, vCores:8>
2017-11-12 12:41:13,935 DEBUG org.apache.hadoop.yarn.server.resourcemanager.scheduler.capacity.CapacityScheduler: Trying to schedule on node: hadoop-worker01, available: <memory:8192, vCores:8>
2017-11-12 12:41:13,935 DEBUG org.apache.hadoop.yarn.server.resourcemanager.scheduler.capacity.ParentQueue: Skip this queue=root, because it doesn't need more resource, schedulingMode=RESPECT_PARTITION_EXCLUSIVITY node-partition=
2017-11-12 12:41:14,431 DEBUG org.apache.hadoop.yarn.server.resourcemanager.scheduler.capacity.CapacityScheduler: nodeUpdate: hadoop-worker03:34047 clusterResources: <memory:24576, vCores:24>
2017-11-12 12:41:14,431 DEBUG org.apache.hadoop.yarn.server.resourcemanager.scheduler.capacity.CapacityScheduler: Node being looked for scheduling hadoop-worker03:34047 availableResource: <memory:8192, vCores:8>
2017-11-12 12:41:14,431 DEBUG org.apache.hadoop.yarn.server.resourcemanager.scheduler.capacity.CapacityScheduler: Trying to schedule on node: hadoop-worker03, available: <memory:8192, vCores:8>
2017-11-12 12:41:14,431 DEBUG org.apache.hadoop.yarn.server.resourcemanager.scheduler.capacity.ParentQueue: Skip this queue=root, because it doesn't need more resource, schedulingMode=RESPECT_PARTITION_EXCLUSIVITY node-partition=
2017-11-12 12:41:14,923 DEBUG org.apache.hadoop.yarn.server.resourcemanager.scheduler.capacity.CapacityScheduler: nodeUpdate: hadoop-worker02:35444 clusterResources: <memory:24576, vCores:24>
2017-11-12 12:41:14,923 DEBUG org.apache.hadoop.yarn.server.resourcemanager.scheduler.capacity.CapacityScheduler: Node being looked for scheduling hadoop-worker02:35444 availableResource: <memory:8192, vCores:8>
2017-11-12 12:41:14,923 DEBUG org.apache.hadoop.yarn.server.resourcemanager.scheduler.capacity.CapacityScheduler: Trying to schedule on node: hadoop-worker02, available: <memory:8192, vCores:8>
2017-11-12 12:41:14,923 DEBUG org.apache.hadoop.yarn.server.resourcemanager.scheduler.capacity.ParentQueue: Skip this queue=root, because it doesn't need more resource, schedulingMode=RESPECT_PARTITION_EXCLUSIVITY node-partition=
2017-11-12 12:41:14,936 DEBUG org.apache.hadoop.yarn.server.resourcemanager.scheduler.capacity.CapacityScheduler: nodeUpdate: hadoop-worker01:41792 clusterResources: <memory:24576, vCores:24>
2017-11-12 12:41:14,937 DEBUG org.apache.hadoop.yarn.server.resourcemanager.scheduler.capacity.CapacityScheduler: Node being looked for scheduling hadoop-worker01:41792 availableResource: <memory:8192, vCores:8>
2017-11-12 12:41:14,937 DEBUG org.apache.hadoop.yarn.server.resourcemanager.scheduler.capacity.CapacityScheduler: Trying to schedule on node: hadoop-worker01, available: <memory:8192, vCores:8>
2017-11-12 12:41:14,937 DEBUG org.apache.hadoop.yarn.server.resourcemanager.scheduler.capacity.ParentQueue: Skip this queue=root, because it doesn't need more resource, schedulingMode=RESPECT_PARTITION_EXCLUSIVITY node-partition=
2017-11-12 12:41:15,432 DEBUG org.apache.hadoop.yarn.server.resourcemanager.scheduler.capacity.CapacityScheduler: nodeUpdate: hadoop-worker03:34047 clusterResources: <memory:24576, vCores:24>
2017-11-12 12:41:15,432 DEBUG org.apache.hadoop.yarn.server.resourcemanager.scheduler.capacity.CapacityScheduler: Node being looked for scheduling hadoop-worker03:34047 availableResource: <memory:8192, vCores:8>
2017-11-12 12:41:15,432 DEBUG org.apache.hadoop.yarn.server.resourcemanager.scheduler.capacity.CapacityScheduler: Trying to schedule on node: hadoop-worker03, available: <memory:8192, vCores:8>
2017-11-12 12:41:15,432 DEBUG org.apache.hadoop.yarn.server.resourcemanager.scheduler.capacity.ParentQueue: Skip this queue=root, because it doesn't need more resource, schedulingMode=RESPECT_PARTITION_EXCLUSIVITY node-partition=
2017-11-12 12:41:15,924 DEBUG org.apache.hadoop.yarn.server.resourcemanager.scheduler.capacity.CapacityScheduler: nodeUpdate: hadoop-worker02:35444 clusterResources: <memory:24576, vCores:24>
2017-11-12 12:41:15,924 DEBUG org.apache.hadoop.yarn.server.resourcemanager.scheduler.capacity.CapacityScheduler: Node being looked for scheduling hadoop-worker02:35444 availableResource: <memory:8192, vCores:8>
2017-11-12 12:41:15,924 DEBUG org.apache.hadoop.yarn.server.resourcemanager.scheduler.capacity.CapacityScheduler: Trying to schedule on node: hadoop-worker02, available: <memory:8192, vCores:8>
2017-11-12 12:41:15,924 DEBUG org.apache.hadoop.yarn.server.resourcemanager.scheduler.capacity.ParentQueue: Skip this queue=root, because it doesn't need more resource, schedulingMode=RESPECT_PARTITION_EXCLUSIVITY node-partition=
2017-11-12 12:41:15,938 DEBUG org.apache.hadoop.yarn.server.resourcemanager.scheduler.capacity.CapacityScheduler: nodeUpdate: hadoop-worker01:41792 clusterResources: <memory:24576, vCores:24>
2017-11-12 12:41:15,938 DEBUG org.apache.hadoop.yarn.server.resourcemanager.scheduler.capacity.CapacityScheduler: Node being looked for scheduling hadoop-worker01:41792 availableResource: <memory:8192, vCores:8>
2017-11-12 12:41:15,938 DEBUG org.apache.hadoop.yarn.server.resourcemanager.scheduler.capacity.CapacityScheduler: Trying to schedule on node: hadoop-worker01, available: <memory:8192, vCores:8>
2017-11-12 12:41:15,938 DEBUG org.apache.hadoop.yarn.server.resourcemanager.scheduler.capacity.ParentQueue: Skip this queue=root, because it doesn't need more resource, schedulingMode=RESPECT_PARTITION_EXCLUSIVITY node-partition=
2017-11-12 12:41:16,433 DEBUG org.apache.hadoop.yarn.server.resourcemanager.scheduler.capacity.CapacityScheduler: nodeUpdate: hadoop-worker03:34047 clusterResources: <memory:24576, vCores:24>
2017-11-12 12:41:16,433 DEBUG org.apache.hadoop.yarn.server.resourcemanager.scheduler.capacity.CapacityScheduler: Node being looked for scheduling hadoop-worker03:34047 availableResource: <memory:8192, vCores:8>
2017-11-12 12:41:16,433 DEBUG org.apache.hadoop.yarn.server.resourcemanager.scheduler.capacity.CapacityScheduler: Trying to schedule on node: hadoop-worker03, available: <memory:8192, vCores:8>
2017-11-12 12:41:16,433 DEBUG org.apache.hadoop.yarn.server.resourcemanager.scheduler.capacity.ParentQueue: Skip this queue=root, because it doesn't need more resource, schedulingMode=RESPECT_PARTITION_EXCLUSIVITY node-partition=
2017-11-12 12:41:16,926 DEBUG org.apache.hadoop.yarn.server.resourcemanager.scheduler.capacity.CapacityScheduler: nodeUpdate: hadoop-worker02:35444 clusterResources: <memory:24576, vCores:24>
2017-11-12 12:41:16,926 DEBUG org.apache.hadoop.yarn.server.resourcemanager.scheduler.capacity.CapacityScheduler: Node being looked for scheduling hadoop-worker02:35444 availableResource: <memory:8192, vCores:8>
2017-11-12 12:41:16,926 DEBUG org.apache.hadoop.yarn.server.resourcemanager.scheduler.capacity.CapacityScheduler: Trying to schedule on node: hadoop-worker02, available: <memory:8192, vCores:8>
2017-11-12 12:41:16,926 DEBUG org.apache.hadoop.yarn.server.resourcemanager.scheduler.capacity.ParentQueue: Skip this queue=root, because it doesn't need more resource, schedulingMode=RESPECT_PARTITION_EXCLUSIVITY node-partition=
2017-11-12 12:41:16,943 DEBUG org.apache.hadoop.yarn.server.resourcemanager.scheduler.capacity.CapacityScheduler: nodeUpdate: hadoop-worker01:41792 clusterResources: <memory:24576, vCores:24>
2017-11-12 12:41:16,944 DEBUG org.apache.hadoop.yarn.server.resourcemanager.scheduler.capacity.CapacityScheduler: Node being looked for scheduling hadoop-worker01:41792 availableResource: <memory:8192, vCores:8>
2017-11-12 12:41:16,944 DEBUG org.apache.hadoop.yarn.server.resourcemanager.scheduler.capacity.CapacityScheduler: Trying to schedule on node: hadoop-worker01, available: <memory:8192, vCores:8>
2017-11-12 12:41:16,944 DEBUG org.apache.hadoop.yarn.server.resourcemanager.scheduler.capacity.ParentQueue: Skip this queue=root, because it doesn't need more resource, schedulingMode=RESPECT_PARTITION_EXCLUSIVITY node-partition=
2017-11-12 12:41:17,434 DEBUG org.apache.hadoop.yarn.server.resourcemanager.scheduler.capacity.CapacityScheduler: nodeUpdate: hadoop-worker03:34047 clusterResources: <memory:24576, vCores:24>
2017-11-12 12:41:17,434 DEBUG org.apache.hadoop.yarn.server.resourcemanager.scheduler.capacity.CapacityScheduler: Node being looked for scheduling hadoop-worker03:34047 availableResource: <memory:8192, vCores:8>
2017-11-12 12:41:17,434 DEBUG org.apache.hadoop.yarn.server.resourcemanager.scheduler.capacity.CapacityScheduler: Trying to schedule on node: hadoop-worker03, available: <memory:8192, vCores:8>
2017-11-12 12:41:17,434 DEBUG org.apache.hadoop.yarn.server.resourcemanager.scheduler.capacity.ParentQueue: Skip this queue=root, because it doesn't need more resource, schedulingMode=RESPECT_PARTITION_EXCLUSIVITY node-partition=
2017-11-12 12:41:17,927 DEBUG org.apache.hadoop.yarn.server.resourcemanager.scheduler.capacity.CapacityScheduler: nodeUpdate: hadoop-worker02:35444 clusterResources: <memory:24576, vCores:24>
2017-11-12 12:41:17,928 DEBUG org.apache.hadoop.yarn.server.resourcemanager.scheduler.capacity.CapacityScheduler: Node being looked for scheduling hadoop-worker02:35444 availableResource: <memory:8192, vCores:8>
2017-11-12 12:41:17,928 DEBUG org.apache.hadoop.yarn.server.resourcemanager.scheduler.capacity.CapacityScheduler: Trying to schedule on node: hadoop-worker02, available: <memory:8192, vCores:8>
2017-11-12 12:41:17,928 DEBUG org.apache.hadoop.yarn.server.resourcemanager.scheduler.capacity.ParentQueue: Skip this queue=root, because it doesn't need more resource, schedulingMode=RESPECT_PARTITION_EXCLUSIVITY node-partition=
2017-11-12 12:41:17,945 DEBUG org.apache.hadoop.yarn.server.resourcemanager.scheduler.capacity.CapacityScheduler: nodeUpdate: hadoop-worker01:41792 clusterResources: <memory:24576, vCores:24>
2017-11-12 12:41:17,945 DEBUG org.apache.hadoop.yarn.server.resourcemanager.scheduler.capacity.CapacityScheduler: Node being looked for scheduling hadoop-worker01:41792 availableResource: <memory:8192, vCores:8>
2017-11-12 12:41:17,945 DEBUG org.apache.hadoop.yarn.server.resourcemanager.scheduler.capacity.CapacityScheduler: Trying to schedule on node: hadoop-worker01, available: <memory:8192, vCores:8>
2017-11-12 12:41:17,945 DEBUG org.apache.hadoop.yarn.server.resourcemanager.scheduler.capacity.ParentQueue: Skip this queue=root, because it doesn't need more resource, schedulingMode=RESPECT_PARTITION_EXCLUSIVITY node-partition=
2017-11-12 12:41:18,436 DEBUG org.apache.hadoop.yarn.server.resourcemanager.scheduler.capacity.CapacityScheduler: nodeUpdate: hadoop-worker03:34047 clusterResources: <memory:24576, vCores:24>
2017-11-12 12:41:18,436 DEBUG org.apache.hadoop.yarn.server.resourcemanager.scheduler.capacity.CapacityScheduler: Node being looked for scheduling hadoop-worker03:34047 availableResource: <memory:8192, vCores:8>
2017-11-12 12:41:18,436 DEBUG org.apache.hadoop.yarn.server.resourcemanager.scheduler.capacity.CapacityScheduler: Trying to schedule on node: hadoop-worker03, available: <memory:8192, vCores:8>
2017-11-12 12:41:18,436 DEBUG org.apache.hadoop.yarn.server.resourcemanager.scheduler.capacity.ParentQueue: Skip this queue=root, because it doesn't need more resource, schedulingMode=RESPECT_PARTITION_EXCLUSIVITY node-partition=
2017-11-12 12:41:18,929 DEBUG org.apache.hadoop.yarn.server.resourcemanager.scheduler.capacity.CapacityScheduler: nodeUpdate: hadoop-worker02:35444 clusterResources: <memory:24576, vCores:24>
2017-11-12 12:41:18,929 DEBUG org.apache.hadoop.yarn.server.resourcemanager.scheduler.capacity.CapacityScheduler: Node being looked for scheduling hadoop-worker02:35444 availableResource: <memory:8192, vCores:8>
2017-11-12 12:41:18,929 DEBUG org.apache.hadoop.yarn.server.resourcemanager.scheduler.capacity.CapacityScheduler: Trying to schedule on node: hadoop-worker02, available: <memory:8192, vCores:8>
2017-11-12 12:41:18,929 DEBUG org.apache.hadoop.yarn.server.resourcemanager.scheduler.capacity.ParentQueue: Skip this queue=root, because it doesn't need more resource, schedulingMode=RESPECT_PARTITION_EXCLUSIVITY node-partition=
2017-11-12 12:41:18,946 DEBUG org.apache.hadoop.yarn.server.resourcemanager.scheduler.capacity.CapacityScheduler: nodeUpdate: hadoop-worker01:41792 clusterResources: <memory:24576, vCores:24>
2017-11-12 12:41:18,946 DEBUG org.apache.hadoop.yarn.server.resourcemanager.scheduler.capacity.CapacityScheduler: Node being looked for scheduling hadoop-worker01:41792 availableResource: <memory:8192, vCores:8>
2017-11-12 12:41:18,946 DEBUG org.apache.hadoop.yarn.server.resourcemanager.scheduler.capacity.CapacityScheduler: Trying to schedule on node: hadoop-worker01, available: <memory:8192, vCores:8>
2017-11-12 12:41:18,946 DEBUG org.apache.hadoop.yarn.server.resourcemanager.scheduler.capacity.ParentQueue: Skip this queue=root, because it doesn't need more resource, schedulingMode=RESPECT_PARTITION_EXCLUSIVITY node-partition=
2017-11-12 12:41:19,438 DEBUG org.apache.hadoop.yarn.server.resourcemanager.scheduler.capacity.CapacityScheduler: nodeUpdate: hadoop-worker03:34047 clusterResources: <memory:24576, vCores:24>
2017-11-12 12:41:19,439 DEBUG org.apache.hadoop.yarn.server.resourcemanager.scheduler.capacity.CapacityScheduler: Node being looked for scheduling hadoop-worker03:34047 availableResource: <memory:8192, vCores:8>
2017-11-12 12:41:19,439 DEBUG org.apache.hadoop.yarn.server.resourcemanager.scheduler.capacity.CapacityScheduler: Trying to schedule on node: hadoop-worker03, available: <memory:8192, vCores:8>
2017-11-12 12:41:19,439 DEBUG org.apache.hadoop.yarn.server.resourcemanager.scheduler.capacity.ParentQueue: Skip this queue=root, because it doesn't need more resource, schedulingMode=RESPECT_PARTITION_EXCLUSIVITY node-partition=
2017-11-12 12:41:19,930 DEBUG org.apache.hadoop.yarn.server.resourcemanager.scheduler.capacity.CapacityScheduler: nodeUpdate: hadoop-worker02:35444 clusterResources: <memory:24576, vCores:24>
2017-11-12 12:41:19,931 DEBUG org.apache.hadoop.yarn.server.resourcemanager.scheduler.capacity.CapacityScheduler: Node being looked for scheduling hadoop-worker02:35444 availableResource: <memory:8192, vCores:8>
2017-11-12 12:41:19,931 DEBUG org.apache.hadoop.yarn.server.resourcemanager.scheduler.capacity.CapacityScheduler: Trying to schedule on node: hadoop-worker02, available: <memory:8192, vCores:8>
2017-11-12 12:41:19,931 DEBUG org.apache.hadoop.yarn.server.resourcemanager.scheduler.capacity.ParentQueue: Skip this queue=root, because it doesn't need more resource, schedulingMode=RESPECT_PARTITION_EXCLUSIVITY node-partition=
2017-11-12 12:41:19,948 DEBUG org.apache.hadoop.yarn.server.resourcemanager.scheduler.capacity.CapacityScheduler: nodeUpdate: hadoop-worker01:41792 clusterResources: <memory:24576, vCores:24>
2017-11-12 12:41:19,948 DEBUG org.apache.hadoop.yarn.server.resourcemanager.scheduler.capacity.CapacityScheduler: Node being looked for scheduling hadoop-worker01:41792 availableResource: <memory:8192, vCores:8>
2017-11-12 12:41:19,948 DEBUG org.apache.hadoop.yarn.server.resourcemanager.scheduler.capacity.CapacityScheduler: Trying to schedule on node: hadoop-worker01, available: <memory:8192, vCores:8>
2017-11-12 12:41:19,948 DEBUG org.apache.hadoop.yarn.server.resourcemanager.scheduler.capacity.ParentQueue: Skip this queue=root, because it doesn't need more resource, schedulingMode=RESPECT_PARTITION_EXCLUSIVITY node-partition=
2017-11-12 12:41:20,440 DEBUG org.apache.hadoop.yarn.server.resourcemanager.scheduler.capacity.CapacityScheduler: nodeUpdate: hadoop-worker03:34047 clusterResources: <memory:24576, vCores:24>
2017-11-12 12:41:20,440 DEBUG org.apache.hadoop.yarn.server.resourcemanager.scheduler.capacity.CapacityScheduler: Node being looked for scheduling hadoop-worker03:34047 availableResource: <memory:8192, vCores:8>
2017-11-12 12:41:20,440 DEBUG org.apache.hadoop.yarn.server.resourcemanager.scheduler.capacity.CapacityScheduler: Trying to schedule on node: hadoop-worker03, available: <memory:8192, vCores:8>
2017-11-12 12:41:20,440 DEBUG org.apache.hadoop.yarn.server.resourcemanager.scheduler.capacity.ParentQueue: Skip this queue=root, because it doesn't need more resource, schedulingMode=RESPECT_PARTITION_EXCLUSIVITY node-partition=
2017-11-12 12:41:20,932 DEBUG org.apache.hadoop.yarn.server.resourcemanager.scheduler.capacity.CapacityScheduler: nodeUpdate: hadoop-worker02:35444 clusterResources: <memory:24576, vCores:24>
2017-11-12 12:41:20,932 DEBUG org.apache.hadoop.yarn.server.resourcemanager.scheduler.capacity.CapacityScheduler: Node being looked for scheduling hadoop-worker02:35444 availableResource: <memory:8192, vCores:8>
2017-11-12 12:41:20,932 DEBUG org.apache.hadoop.yarn.server.resourcemanager.scheduler.capacity.CapacityScheduler: Trying to schedule on node: hadoop-worker02, available: <memory:8192, vCores:8>
2017-11-12 12:41:20,933 DEBUG org.apache.hadoop.yarn.server.resourcemanager.scheduler.capacity.ParentQueue: Skip this queue=root, because it doesn't need more resource, schedulingMode=RESPECT_PARTITION_EXCLUSIVITY node-partition=
2017-11-12 12:41:20,950 DEBUG org.apache.hadoop.yarn.server.resourcemanager.scheduler.capacity.CapacityScheduler: nodeUpdate: hadoop-worker01:41792 clusterResources: <memory:24576, vCores:24>
2017-11-12 12:41:20,950 DEBUG org.apache.hadoop.yarn.server.resourcemanager.scheduler.capacity.CapacityScheduler: Node being looked for scheduling hadoop-worker01:41792 availableResource: <memory:8192, vCores:8>
2017-11-12 12:41:20,950 DEBUG org.apache.hadoop.yarn.server.resourcemanager.scheduler.capacity.CapacityScheduler: Trying to schedule on node: hadoop-worker01, available: <memory:8192, vCores:8>
2017-11-12 12:41:20,950 DEBUG org.apache.hadoop.yarn.server.resourcemanager.scheduler.capacity.ParentQueue: Skip this queue=root, because it doesn't need more resource, schedulingMode=RESPECT_PARTITION_EXCLUSIVITY node-partition=
2017-11-12 12:41:21,442 DEBUG org.apache.hadoop.yarn.server.resourcemanager.scheduler.capacity.CapacityScheduler: nodeUpdate: hadoop-worker03:34047 clusterResources: <memory:24576, vCores:24>
2017-11-12 12:41:21,442 DEBUG org.apache.hadoop.yarn.server.resourcemanager.scheduler.capacity.CapacityScheduler: Node being looked for scheduling hadoop-worker03:34047 availableResource: <memory:8192, vCores:8>
2017-11-12 12:41:21,442 DEBUG org.apache.hadoop.yarn.server.resourcemanager.scheduler.capacity.CapacityScheduler: Trying to schedule on node: hadoop-worker03, available: <memory:8192, vCores:8>
2017-11-12 12:41:21,442 DEBUG org.apache.hadoop.yarn.server.resourcemanager.scheduler.capacity.ParentQueue: Skip this queue=root, because it doesn't need more resource, schedulingMode=RESPECT_PARTITION_EXCLUSIVITY node-partition=
2017-11-12 12:41:21,934 DEBUG org.apache.hadoop.yarn.server.resourcemanager.scheduler.capacity.CapacityScheduler: nodeUpdate: hadoop-worker02:35444 clusterResources: <memory:24576, vCores:24>
2017-11-12 12:41:21,934 DEBUG org.apache.hadoop.yarn.server.resourcemanager.scheduler.capacity.CapacityScheduler: Node being looked for scheduling hadoop-worker02:35444 availableResource: <memory:8192, vCores:8>
2017-11-12 12:41:21,934 DEBUG org.apache.hadoop.yarn.server.resourcemanager.scheduler.capacity.CapacityScheduler: Trying to schedule on node: hadoop-worker02, available: <memory:8192, vCores:8>
2017-11-12 12:41:21,934 DEBUG org.apache.hadoop.yarn.server.resourcemanager.scheduler.capacity.ParentQueue: Skip this queue=root, because it doesn't need more resource, schedulingMode=RESPECT_PARTITION_EXCLUSIVITY node-partition=
2017-11-12 12:41:21,951 DEBUG org.apache.hadoop.yarn.server.resourcemanager.scheduler.capacity.CapacityScheduler: nodeUpdate: hadoop-worker01:41792 clusterResources: <memory:24576, vCores:24>
2017-11-12 12:41:21,951 DEBUG org.apache.hadoop.yarn.server.resourcemanager.scheduler.capacity.CapacityScheduler: Node being looked for scheduling hadoop-worker01:41792 availableResource: <memory:8192, vCores:8>
2017-11-12 12:41:21,951 DEBUG org.apache.hadoop.yarn.server.resourcemanager.scheduler.capacity.CapacityScheduler: Trying to schedule on node: hadoop-worker01, available: <memory:8192, vCores:8>
2017-11-12 12:41:21,951 DEBUG org.apache.hadoop.yarn.server.resourcemanager.scheduler.capacity.ParentQueue: Skip this queue=root, because it doesn't need more resource, schedulingMode=RESPECT_PARTITION_EXCLUSIVITY node-partition=
2017-11-12 12:41:22,443 DEBUG org.apache.hadoop.yarn.server.resourcemanager.scheduler.capacity.CapacityScheduler: nodeUpdate: hadoop-worker03:34047 clusterResources: <memory:24576, vCores:24>
2017-11-12 12:41:22,443 DEBUG org.apache.hadoop.yarn.server.resourcemanager.scheduler.capacity.CapacityScheduler: Node being looked for scheduling hadoop-worker03:34047 availableResource: <memory:8192, vCores:8>
2017-11-12 12:41:22,443 DEBUG org.apache.hadoop.yarn.server.resourcemanager.scheduler.capacity.CapacityScheduler: Trying to schedule on node: hadoop-worker03, available: <memory:8192, vCores:8>
2017-11-12 12:41:22,443 DEBUG org.apache.hadoop.yarn.server.resourcemanager.scheduler.capacity.ParentQueue: Skip this queue=root, because it doesn't need more resource, schedulingMode=RESPECT_PARTITION_EXCLUSIVITY node-partition=
2017-11-12 12:41:22,935 DEBUG org.apache.hadoop.yarn.server.resourcemanager.scheduler.capacity.CapacityScheduler: nodeUpdate: hadoop-worker02:35444 clusterResources: <memory:24576, vCores:24>
2017-11-12 12:41:22,935 DEBUG org.apache.hadoop.yarn.server.resourcemanager.scheduler.capacity.CapacityScheduler: Node being looked for scheduling hadoop-worker02:35444 availableResource: <memory:8192, vCores:8>
2017-11-12 12:41:22,936 DEBUG org.apache.hadoop.yarn.server.resourcemanager.scheduler.capacity.CapacityScheduler: Trying to schedule on node: hadoop-worker02, available: <memory:8192, vCores:8>
2017-11-12 12:41:22,936 DEBUG org.apache.hadoop.yarn.server.resourcemanager.scheduler.capacity.ParentQueue: Skip this queue=root, because it doesn't need more resource, schedulingMode=RESPECT_PARTITION_EXCLUSIVITY node-partition=
2017-11-12 12:41:22,961 DEBUG org.apache.hadoop.yarn.server.resourcemanager.scheduler.capacity.CapacityScheduler: nodeUpdate: hadoop-worker01:41792 clusterResources: <memory:24576, vCores:24>
2017-11-12 12:41:22,961 DEBUG org.apache.hadoop.yarn.server.resourcemanager.scheduler.capacity.CapacityScheduler: Node being looked for scheduling hadoop-worker01:41792 availableResource: <memory:8192, vCores:8>
2017-11-12 12:41:22,961 DEBUG org.apache.hadoop.yarn.server.resourcemanager.scheduler.capacity.CapacityScheduler: Trying to schedule on node: hadoop-worker01, available: <memory:8192, vCores:8>
2017-11-12 12:41:22,961 DEBUG org.apache.hadoop.yarn.server.resourcemanager.scheduler.capacity.ParentQueue: Skip this queue=root, because it doesn't need more resource, schedulingMode=RESPECT_PARTITION_EXCLUSIVITY node-partition=
2017-11-12 12:41:23,445 DEBUG org.apache.hadoop.yarn.server.resourcemanager.scheduler.capacity.CapacityScheduler: nodeUpdate: hadoop-worker03:34047 clusterResources: <memory:24576, vCores:24>
2017-11-12 12:41:23,445 DEBUG org.apache.hadoop.yarn.server.resourcemanager.scheduler.capacity.CapacityScheduler: Node being looked for scheduling hadoop-worker03:34047 availableResource: <memory:8192, vCores:8>
2017-11-12 12:41:23,445 DEBUG org.apache.hadoop.yarn.server.resourcemanager.scheduler.capacity.CapacityScheduler: Trying to schedule on node: hadoop-worker03, available: <memory:8192, vCores:8>
2017-11-12 12:41:23,445 DEBUG org.apache.hadoop.yarn.server.resourcemanager.scheduler.capacity.ParentQueue: Skip this queue=root, because it doesn't need more resource, schedulingMode=RESPECT_PARTITION_EXCLUSIVITY node-partition=
2017-11-12 12:41:23,938 DEBUG org.apache.hadoop.yarn.server.resourcemanager.scheduler.capacity.CapacityScheduler: nodeUpdate: hadoop-worker02:35444 clusterResources: <memory:24576, vCores:24>
2017-11-12 12:41:23,938 DEBUG org.apache.hadoop.yarn.server.resourcemanager.scheduler.capacity.CapacityScheduler: Node being looked for scheduling hadoop-worker02:35444 availableResource: <memory:8192, vCores:8>
2017-11-12 12:41:23,938 DEBUG org.apache.hadoop.yarn.server.resourcemanager.scheduler.capacity.CapacityScheduler: Trying to schedule on node: hadoop-worker02, available: <memory:8192, vCores:8>
2017-11-12 12:41:23,939 DEBUG org.apache.hadoop.yarn.server.resourcemanager.scheduler.capacity.ParentQueue: Skip this queue=root, because it doesn't need more resource, schedulingMode=RESPECT_PARTITION_EXCLUSIVITY node-partition=
2017-11-12 12:41:23,963 DEBUG org.apache.hadoop.yarn.server.resourcemanager.scheduler.capacity.CapacityScheduler: nodeUpdate: hadoop-worker01:41792 clusterResources: <memory:24576, vCores:24>
2017-11-12 12:41:23,963 DEBUG org.apache.hadoop.yarn.server.resourcemanager.scheduler.capacity.CapacityScheduler: Node being looked for scheduling hadoop-worker01:41792 availableResource: <memory:8192, vCores:8>
2017-11-12 12:41:23,963 DEBUG org.apache.hadoop.yarn.server.resourcemanager.scheduler.capacity.CapacityScheduler: Trying to schedule on node: hadoop-worker01, available: <memory:8192, vCores:8>
2017-11-12 12:41:23,963 DEBUG org.apache.hadoop.yarn.server.resourcemanager.scheduler.capacity.ParentQueue: Skip this queue=root, because it doesn't need more resource, schedulingMode=RESPECT_PARTITION_EXCLUSIVITY node-partition=
2017-11-12 12:41:24,446 DEBUG org.apache.hadoop.yarn.server.resourcemanager.scheduler.capacity.CapacityScheduler: nodeUpdate: hadoop-worker03:34047 clusterResources: <memory:24576, vCores:24>
2017-11-12 12:41:24,446 DEBUG org.apache.hadoop.yarn.server.resourcemanager.scheduler.capacity.CapacityScheduler: Node being looked for scheduling hadoop-worker03:34047 availableResource: <memory:8192, vCores:8>
2017-11-12 12:41:24,446 DEBUG org.apache.hadoop.yarn.server.resourcemanager.scheduler.capacity.CapacityScheduler: Trying to schedule on node: hadoop-worker03, available: <memory:8192, vCores:8>
2017-11-12 12:41:24,446 DEBUG org.apache.hadoop.yarn.server.resourcemanager.scheduler.capacity.ParentQueue: Skip this queue=root, because it doesn't need more resource, schedulingMode=RESPECT_PARTITION_EXCLUSIVITY node-partition=
2017-11-12 12:41:24,941 DEBUG org.apache.hadoop.yarn.server.resourcemanager.scheduler.capacity.CapacityScheduler: nodeUpdate: hadoop-worker02:35444 clusterResources: <memory:24576, vCores:24>
2017-11-12 12:41:24,941 DEBUG org.apache.hadoop.yarn.server.resourcemanager.scheduler.capacity.CapacityScheduler: Node being looked for scheduling hadoop-worker02:35444 availableResource: <memory:8192, vCores:8>
2017-11-12 12:41:24,941 DEBUG org.apache.hadoop.yarn.server.resourcemanager.scheduler.capacity.CapacityScheduler: Trying to schedule on node: hadoop-worker02, available: <memory:8192, vCores:8>
2017-11-12 12:41:24,941 DEBUG org.apache.hadoop.yarn.server.resourcemanager.scheduler.capacity.ParentQueue: Skip this queue=root, because it doesn't need more resource, schedulingMode=RESPECT_PARTITION_EXCLUSIVITY node-partition=
2017-11-12 12:41:24,964 DEBUG org.apache.hadoop.yarn.server.resourcemanager.scheduler.capacity.CapacityScheduler: nodeUpdate: hadoop-worker01:41792 clusterResources: <memory:24576, vCores:24>
2017-11-12 12:41:24,964 DEBUG org.apache.hadoop.yarn.server.resourcemanager.scheduler.capacity.CapacityScheduler: Node being looked for scheduling hadoop-worker01:41792 availableResource: <memory:8192, vCores:8>
2017-11-12 12:41:24,964 DEBUG org.apache.hadoop.yarn.server.resourcemanager.scheduler.capacity.CapacityScheduler: Trying to schedule on node: hadoop-worker01, available: <memory:8192, vCores:8>
2017-11-12 12:41:24,964 DEBUG org.apache.hadoop.yarn.server.resourcemanager.scheduler.capacity.ParentQueue: Skip this queue=root, because it doesn't need more resource, schedulingMode=RESPECT_PARTITION_EXCLUSIVITY node-partition=
2017-11-12 12:41:32,273 DEBUG org.apache.hadoop.yarn.server.resourcemanager.scheduler.capacity.CapacityScheduler: nodeUpdate: hadoop-worker03:34047 clusterResources: <memory:24576, vCores:24>
2017-11-12 12:41:32,273 DEBUG org.apache.hadoop.yarn.server.resourcemanager.scheduler.capacity.CapacityScheduler: Node being looked for scheduling hadoop-worker03:34047 availableResource: <memory:8192, vCores:8>
2017-11-12 12:41:32,273 DEBUG org.apache.hadoop.yarn.server.resourcemanager.scheduler.capacity.CapacityScheduler: Trying to schedule on node: hadoop-worker03, available: <memory:8192, vCores:8>
2017-11-12 12:41:32,273 DEBUG org.apache.hadoop.yarn.server.resourcemanager.scheduler.capacity.ParentQueue: Skip this queue=root, because it doesn't need more resource, schedulingMode=RESPECT_PARTITION_EXCLUSIVITY node-partition=
2017-11-12 12:41:32,825 DEBUG org.apache.hadoop.yarn.server.resourcemanager.scheduler.capacity.CapacityScheduler: nodeUpdate: hadoop-worker02:35444 clusterResources: <memory:24576, vCores:24>
2017-11-12 12:41:32,825 DEBUG org.apache.hadoop.yarn.server.resourcemanager.scheduler.capacity.CapacityScheduler: Node being looked for scheduling hadoop-worker02:35444 availableResource: <memory:8192, vCores:8>
2017-11-12 12:41:32,825 DEBUG org.apache.hadoop.yarn.server.resourcemanager.scheduler.capacity.CapacityScheduler: Trying to schedule on node: hadoop-worker02, available: <memory:8192, vCores:8>
2017-11-12 12:41:32,825 DEBUG org.apache.hadoop.yarn.server.resourcemanager.scheduler.capacity.ParentQueue: Skip this queue=root, because it doesn't need more resource, schedulingMode=RESPECT_PARTITION_EXCLUSIVITY node-partition=
2017-11-12 12:41:32,849 DEBUG org.apache.hadoop.yarn.server.resourcemanager.scheduler.capacity.CapacityScheduler: nodeUpdate: hadoop-worker01:41792 clusterResources: <memory:24576, vCores:24>
2017-11-12 12:41:32,849 DEBUG org.apache.hadoop.yarn.server.resourcemanager.scheduler.capacity.CapacityScheduler: Node being looked for scheduling hadoop-worker01:41792 availableResource: <memory:8192, vCores:8>
2017-11-12 12:41:32,849 DEBUG org.apache.hadoop.yarn.server.resourcemanager.scheduler.capacity.CapacityScheduler: Trying to schedule on node: hadoop-worker01, available: <memory:8192, vCores:8>
2017-11-12 12:41:32,849 DEBUG org.apache.hadoop.yarn.server.resourcemanager.scheduler.capacity.ParentQueue: Skip this queue=root, because it doesn't need more resource, schedulingMode=RESPECT_PARTITION_EXCLUSIVITY node-partition=
2017-11-12 12:41:33,347 DEBUG org.apache.hadoop.yarn.server.resourcemanager.scheduler.capacity.CapacityScheduler: nodeUpdate: hadoop-worker03:34047 clusterResources: <memory:24576, vCores:24>
2017-11-12 12:41:33,347 DEBUG org.apache.hadoop.yarn.server.resourcemanager.scheduler.capacity.CapacityScheduler: Node being looked for scheduling hadoop-worker03:34047 availableResource: <memory:8192, vCores:8>
2017-11-12 12:41:33,347 DEBUG org.apache.hadoop.yarn.server.resourcemanager.scheduler.capacity.CapacityScheduler: Trying to schedule on node: hadoop-worker03, available: <memory:8192, vCores:8>
2017-11-12 12:41:33,347 DEBUG org.apache.hadoop.yarn.server.resourcemanager.scheduler.capacity.ParentQueue: Skip this queue=root, because it doesn't need more resource, schedulingMode=RESPECT_PARTITION_EXCLUSIVITY node-partition=
2017-11-12 12:41:33,843 DEBUG org.apache.hadoop.yarn.server.resourcemanager.scheduler.capacity.CapacityScheduler: nodeUpdate: hadoop-worker02:35444 clusterResources: <memory:24576, vCores:24>
2017-11-12 12:41:33,843 DEBUG org.apache.hadoop.yarn.server.resourcemanager.scheduler.capacity.CapacityScheduler: Node being looked for scheduling hadoop-worker02:35444 availableResource: <memory:8192, vCores:8>
2017-11-12 12:41:33,843 DEBUG org.apache.hadoop.yarn.server.resourcemanager.scheduler.capacity.CapacityScheduler: Trying to schedule on node: hadoop-worker02, available: <memory:8192, vCores:8>
2017-11-12 12:41:33,843 DEBUG org.apache.hadoop.yarn.server.resourcemanager.scheduler.capacity.ParentQueue: Skip this queue=root, because it doesn't need more resource, schedulingMode=RESPECT_PARTITION_EXCLUSIVITY node-partition=
2017-11-12 12:41:33,865 DEBUG org.apache.hadoop.yarn.server.resourcemanager.scheduler.capacity.CapacityScheduler: nodeUpdate: hadoop-worker01:41792 clusterResources: <memory:24576, vCores:24>
2017-11-12 12:41:33,866 DEBUG org.apache.hadoop.yarn.server.resourcemanager.scheduler.capacity.CapacityScheduler: Node being looked for scheduling hadoop-worker01:41792 availableResource: <memory:8192, vCores:8>
2017-11-12 12:41:33,866 DEBUG org.apache.hadoop.yarn.server.resourcemanager.scheduler.capacity.CapacityScheduler: Trying to schedule on node: hadoop-worker01, available: <memory:8192, vCores:8>
2017-11-12 12:41:33,866 DEBUG org.apache.hadoop.yarn.server.resourcemanager.scheduler.capacity.ParentQueue: Skip this queue=root, because it doesn't need more resource, schedulingMode=RESPECT_PARTITION_EXCLUSIVITY node-partition=
2017-11-12 12:41:34,348 DEBUG org.apache.hadoop.yarn.server.resourcemanager.scheduler.capacity.CapacityScheduler: nodeUpdate: hadoop-worker03:34047 clusterResources: <memory:24576, vCores:24>
2017-11-12 12:41:34,349 DEBUG org.apache.hadoop.yarn.server.resourcemanager.scheduler.capacity.CapacityScheduler: Node being looked for scheduling hadoop-worker03:34047 availableResource: <memory:8192, vCores:8>
2017-11-12 12:41:34,349 DEBUG org.apache.hadoop.yarn.server.resourcemanager.scheduler.capacity.CapacityScheduler: Trying to schedule on node: hadoop-worker03, available: <memory:8192, vCores:8>
2017-11-12 12:41:34,349 DEBUG org.apache.hadoop.yarn.server.resourcemanager.scheduler.capacity.ParentQueue: Skip this queue=root, because it doesn't need more resource, schedulingMode=RESPECT_PARTITION_EXCLUSIVITY node-partition=
2017-11-12 12:41:34,748 DEBUG org.apache.hadoop.yarn.server.resourcemanager.scheduler.capacity.CapacityScheduler: nodeUpdate: hadoop-worker02:35444 clusterResources: <memory:24576, vCores:24>
2017-11-12 12:41:34,748 DEBUG org.apache.hadoop.yarn.server.resourcemanager.scheduler.capacity.CapacityScheduler: Node being looked for scheduling hadoop-worker02:35444 availableResource: <memory:8192, vCores:8>
2017-11-12 12:41:34,748 DEBUG org.apache.hadoop.yarn.server.resourcemanager.scheduler.capacity.CapacityScheduler: Trying to schedule on node: hadoop-worker02, available: <memory:8192, vCores:8>
2017-11-12 12:41:34,748 DEBUG org.apache.hadoop.yarn.server.resourcemanager.scheduler.capacity.ParentQueue: Skip this queue=root, because it doesn't need more resource, schedulingMode=RESPECT_PARTITION_EXCLUSIVITY node-partition=
2017-11-12 12:41:34,859 DEBUG org.apache.hadoop.yarn.server.resourcemanager.scheduler.capacity.CapacityScheduler: nodeUpdate: hadoop-worker01:41792 clusterResources: <memory:24576, vCores:24>
2017-11-12 12:41:34,860 DEBUG org.apache.hadoop.yarn.server.resourcemanager.scheduler.capacity.CapacityScheduler: Node being looked for scheduling hadoop-worker01:41792 availableResource: <memory:8192, vCores:8>
2017-11-12 12:41:34,860 DEBUG org.apache.hadoop.yarn.server.resourcemanager.scheduler.capacity.CapacityScheduler: Trying to schedule on node: hadoop-worker01, available: <memory:8192, vCores:8>
2017-11-12 12:41:34,860 DEBUG org.apache.hadoop.yarn.server.resourcemanager.scheduler.capacity.ParentQueue: Skip this queue=root, because it doesn't need more resource, schedulingMode=RESPECT_PARTITION_EXCLUSIVITY node-partition=
2017-11-12 12:41:35,350 DEBUG org.apache.hadoop.yarn.server.resourcemanager.scheduler.capacity.CapacityScheduler: nodeUpdate: hadoop-worker03:34047 clusterResources: <memory:24576, vCores:24>
2017-11-12 12:41:35,350 DEBUG org.apache.hadoop.yarn.server.resourcemanager.scheduler.capacity.CapacityScheduler: Node being looked for scheduling hadoop-worker03:34047 availableResource: <memory:8192, vCores:8>
2017-11-12 12:41:35,350 DEBUG org.apache.hadoop.yarn.server.resourcemanager.scheduler.capacity.CapacityScheduler: Trying to schedule on node: hadoop-worker03, available: <memory:8192, vCores:8>
2017-11-12 12:41:35,350 DEBUG org.apache.hadoop.yarn.server.resourcemanager.scheduler.capacity.ParentQueue: Skip this queue=root, because it doesn't need more resource, schedulingMode=RESPECT_PARTITION_EXCLUSIVITY node-partition=
2017-11-12 12:41:35,649 DEBUG org.apache.hadoop.yarn.server.resourcemanager.scheduler.capacity.CapacityScheduler: nodeUpdate: hadoop-worker02:35444 clusterResources: <memory:24576, vCores:24>
2017-11-12 12:41:35,649 DEBUG org.apache.hadoop.yarn.server.resourcemanager.scheduler.capacity.CapacityScheduler: Node being looked for scheduling hadoop-worker02:35444 availableResource: <memory:8192, vCores:8>
2017-11-12 12:41:35,650 DEBUG org.apache.hadoop.yarn.server.resourcemanager.scheduler.capacity.CapacityScheduler: Trying to schedule on node: hadoop-worker02, available: <memory:8192, vCores:8>
2017-11-12 12:41:35,650 DEBUG org.apache.hadoop.yarn.server.resourcemanager.scheduler.capacity.ParentQueue: Skip this queue=root, because it doesn't need more resource, schedulingMode=RESPECT_PARTITION_EXCLUSIVITY node-partition=
2017-11-12 12:41:35,845 DEBUG org.apache.hadoop.yarn.server.resourcemanager.scheduler.capacity.CapacityScheduler: nodeUpdate: hadoop-worker01:41792 clusterResources: <memory:24576, vCores:24>
2017-11-12 12:41:35,845 DEBUG org.apache.hadoop.yarn.server.resourcemanager.scheduler.capacity.CapacityScheduler: Node being looked for scheduling hadoop-worker01:41792 availableResource: <memory:8192, vCores:8>
2017-11-12 12:41:35,845 DEBUG org.apache.hadoop.yarn.server.resourcemanager.scheduler.capacity.CapacityScheduler: Trying to schedule on node: hadoop-worker01, available: <memory:8192, vCores:8>
2017-11-12 12:41:35,845 DEBUG org.apache.hadoop.yarn.server.resourcemanager.scheduler.capacity.ParentQueue: Skip this queue=root, because it doesn't need more resource, schedulingMode=RESPECT_PARTITION_EXCLUSIVITY node-partition=
2017-11-12 12:41:36,352 DEBUG org.apache.hadoop.yarn.server.resourcemanager.scheduler.capacity.CapacityScheduler: nodeUpdate: hadoop-worker03:34047 clusterResources: <memory:24576, vCores:24>
2017-11-12 12:41:36,352 DEBUG org.apache.hadoop.yarn.server.resourcemanager.scheduler.capacity.CapacityScheduler: Node being looked for scheduling hadoop-worker03:34047 availableResource: <memory:8192, vCores:8>
2017-11-12 12:41:36,352 DEBUG org.apache.hadoop.yarn.server.resourcemanager.scheduler.capacity.CapacityScheduler: Trying to schedule on node: hadoop-worker03, available: <memory:8192, vCores:8>
2017-11-12 12:41:36,352 DEBUG org.apache.hadoop.yarn.server.resourcemanager.scheduler.capacity.ParentQueue: Skip this queue=root, because it doesn't need more resource, schedulingMode=RESPECT_PARTITION_EXCLUSIVITY node-partition=
2017-11-12 12:41:36,647 DEBUG org.apache.hadoop.yarn.server.resourcemanager.scheduler.capacity.CapacityScheduler: nodeUpdate: hadoop-worker02:35444 clusterResources: <memory:24576, vCores:24>
2017-11-12 12:41:36,647 DEBUG org.apache.hadoop.yarn.server.resourcemanager.scheduler.capacity.CapacityScheduler: Node being looked for scheduling hadoop-worker02:35444 availableResource: <memory:8192, vCores:8>
2017-11-12 12:41:36,647 DEBUG org.apache.hadoop.yarn.server.resourcemanager.scheduler.capacity.CapacityScheduler: Trying to schedule on node: hadoop-worker02, available: <memory:8192, vCores:8>
2017-11-12 12:41:36,647 DEBUG org.apache.hadoop.yarn.server.resourcemanager.scheduler.capacity.ParentQueue: Skip this queue=root, because it doesn't need more resource, schedulingMode=RESPECT_PARTITION_EXCLUSIVITY node-partition=
2017-11-12 12:41:36,847 DEBUG org.apache.hadoop.yarn.server.resourcemanager.scheduler.capacity.CapacityScheduler: nodeUpdate: hadoop-worker01:41792 clusterResources: <memory:24576, vCores:24>
2017-11-12 12:41:36,847 DEBUG org.apache.hadoop.yarn.server.resourcemanager.scheduler.capacity.CapacityScheduler: Node being looked for scheduling hadoop-worker01:41792 availableResource: <memory:8192, vCores:8>
2017-11-12 12:41:36,847 DEBUG org.apache.hadoop.yarn.server.resourcemanager.scheduler.capacity.CapacityScheduler: Trying to schedule on node: hadoop-worker01, available: <memory:8192, vCores:8>
2017-11-12 12:41:36,847 DEBUG org.apache.hadoop.yarn.server.resourcemanager.scheduler.capacity.ParentQueue: Skip this queue=root, because it doesn't need more resource, schedulingMode=RESPECT_PARTITION_EXCLUSIVITY node-partition=
2017-11-12 12:41:37,353 DEBUG org.apache.hadoop.yarn.server.resourcemanager.scheduler.capacity.CapacityScheduler: nodeUpdate: hadoop-worker03:34047 clusterResources: <memory:24576, vCores:24>
2017-11-12 12:41:37,353 DEBUG org.apache.hadoop.yarn.server.resourcemanager.scheduler.capacity.CapacityScheduler: Node being looked for scheduling hadoop-worker03:34047 availableResource: <memory:8192, vCores:8>
2017-11-12 12:41:37,353 DEBUG org.apache.hadoop.yarn.server.resourcemanager.scheduler.capacity.CapacityScheduler: Trying to schedule on node: hadoop-worker03, available: <memory:8192, vCores:8>
2017-11-12 12:41:37,353 DEBUG org.apache.hadoop.yarn.server.resourcemanager.scheduler.capacity.ParentQueue: Skip this queue=root, because it doesn't need more resource, schedulingMode=RESPECT_PARTITION_EXCLUSIVITY node-partition=
2017-11-12 12:41:37,648 DEBUG org.apache.hadoop.yarn.server.resourcemanager.scheduler.capacity.CapacityScheduler: nodeUpdate: hadoop-worker02:35444 clusterResources: <memory:24576, vCores:24>
2017-11-12 12:41:37,648 DEBUG org.apache.hadoop.yarn.server.resourcemanager.scheduler.capacity.CapacityScheduler: Node being looked for scheduling hadoop-worker02:35444 availableResource: <memory:8192, vCores:8>
2017-11-12 12:41:37,648 DEBUG org.apache.hadoop.yarn.server.resourcemanager.scheduler.capacity.CapacityScheduler: Trying to schedule on node: hadoop-worker02, available: <memory:8192, vCores:8>
2017-11-12 12:41:37,648 DEBUG org.apache.hadoop.yarn.server.resourcemanager.scheduler.capacity.ParentQueue: Skip this queue=root, because it doesn't need more resource, schedulingMode=RESPECT_PARTITION_EXCLUSIVITY node-partition=
2017-11-12 12:41:37,848 DEBUG org.apache.hadoop.yarn.server.resourcemanager.scheduler.capacity.CapacityScheduler: nodeUpdate: hadoop-worker01:41792 clusterResources: <memory:24576, vCores:24>
2017-11-12 12:41:37,848 DEBUG org.apache.hadoop.yarn.server.resourcemanager.scheduler.capacity.CapacityScheduler: Node being looked for scheduling hadoop-worker01:41792 availableResource: <memory:8192, vCores:8>
2017-11-12 12:41:37,848 DEBUG org.apache.hadoop.yarn.server.resourcemanager.scheduler.capacity.CapacityScheduler: Trying to schedule on node: hadoop-worker01, available: <memory:8192, vCores:8>
2017-11-12 12:41:37,848 DEBUG org.apache.hadoop.yarn.server.resourcemanager.scheduler.capacity.ParentQueue: Skip this queue=root, because it doesn't need more resource, schedulingMode=RESPECT_PARTITION_EXCLUSIVITY node-partition=
2017-11-12 12:41:38,354 DEBUG org.apache.hadoop.yarn.server.resourcemanager.scheduler.capacity.CapacityScheduler: nodeUpdate: hadoop-worker03:34047 clusterResources: <memory:24576, vCores:24>
2017-11-12 12:41:38,354 DEBUG org.apache.hadoop.yarn.server.resourcemanager.scheduler.capacity.CapacityScheduler: Node being looked for scheduling hadoop-worker03:34047 availableResource: <memory:8192, vCores:8>
2017-11-12 12:41:38,354 DEBUG org.apache.hadoop.yarn.server.resourcemanager.scheduler.capacity.CapacityScheduler: Trying to schedule on node: hadoop-worker03, available: <memory:8192, vCores:8>
2017-11-12 12:41:38,354 DEBUG org.apache.hadoop.yarn.server.resourcemanager.scheduler.capacity.ParentQueue: Skip this queue=root, because it doesn't need more resource, schedulingMode=RESPECT_PARTITION_EXCLUSIVITY node-partition=
2017-11-12 12:41:38,649 DEBUG org.apache.hadoop.yarn.server.resourcemanager.scheduler.capacity.CapacityScheduler: nodeUpdate: hadoop-worker02:35444 clusterResources: <memory:24576, vCores:24>
2017-11-12 12:41:38,649 DEBUG org.apache.hadoop.yarn.server.resourcemanager.scheduler.capacity.CapacityScheduler: Node being looked for scheduling hadoop-worker02:35444 availableResource: <memory:8192, vCores:8>
2017-11-12 12:41:38,649 DEBUG org.apache.hadoop.yarn.server.resourcemanager.scheduler.capacity.CapacityScheduler: Trying to schedule on node: hadoop-worker02, available: <memory:8192, vCores:8>
2017-11-12 12:41:38,649 DEBUG org.apache.hadoop.yarn.server.resourcemanager.scheduler.capacity.ParentQueue: Skip this queue=root, because it doesn't need more resource, schedulingMode=RESPECT_PARTITION_EXCLUSIVITY node-partition=
2017-11-12 12:41:38,850 DEBUG org.apache.hadoop.yarn.server.resourcemanager.scheduler.capacity.CapacityScheduler: nodeUpdate: hadoop-worker01:41792 clusterResources: <memory:24576, vCores:24>
2017-11-12 12:41:38,850 DEBUG org.apache.hadoop.yarn.server.resourcemanager.scheduler.capacity.CapacityScheduler: Node being looked for scheduling hadoop-worker01:41792 availableResource: <memory:8192, vCores:8>
2017-11-12 12:41:38,850 DEBUG org.apache.hadoop.yarn.server.resourcemanager.scheduler.capacity.CapacityScheduler: Trying to schedule on node: hadoop-worker01, available: <memory:8192, vCores:8>
2017-11-12 12:41:38,850 DEBUG org.apache.hadoop.yarn.server.resourcemanager.scheduler.capacity.ParentQueue: Skip this queue=root, because it doesn't need more resource, schedulingMode=RESPECT_PARTITION_EXCLUSIVITY node-partition=
2017-11-12 12:41:39,355 DEBUG org.apache.hadoop.yarn.server.resourcemanager.scheduler.capacity.CapacityScheduler: nodeUpdate: hadoop-worker03:34047 clusterResources: <memory:24576, vCores:24>
2017-11-12 12:41:39,355 DEBUG org.apache.hadoop.yarn.server.resourcemanager.scheduler.capacity.CapacityScheduler: Node being looked for scheduling hadoop-worker03:34047 availableResource: <memory:8192, vCores:8>
2017-11-12 12:41:39,355 DEBUG org.apache.hadoop.yarn.server.resourcemanager.scheduler.capacity.CapacityScheduler: Trying to schedule on node: hadoop-worker03, available: <memory:8192, vCores:8>
2017-11-12 12:41:39,355 DEBUG org.apache.hadoop.yarn.server.resourcemanager.scheduler.capacity.ParentQueue: Skip this queue=root, because it doesn't need more resource, schedulingMode=RESPECT_PARTITION_EXCLUSIVITY node-partition=
2017-11-12 12:41:39,650 DEBUG org.apache.hadoop.yarn.server.resourcemanager.scheduler.capacity.CapacityScheduler: nodeUpdate: hadoop-worker02:35444 clusterResources: <memory:24576, vCores:24>
2017-11-12 12:41:39,650 DEBUG org.apache.hadoop.yarn.server.resourcemanager.scheduler.capacity.CapacityScheduler: Node being looked for scheduling hadoop-worker02:35444 availableResource: <memory:8192, vCores:8>
2017-11-12 12:41:39,650 DEBUG org.apache.hadoop.yarn.server.resourcemanager.scheduler.capacity.CapacityScheduler: Trying to schedule on node: hadoop-worker02, available: <memory:8192, vCores:8>
2017-11-12 12:41:39,650 DEBUG org.apache.hadoop.yarn.server.resourcemanager.scheduler.capacity.ParentQueue: Skip this queue=root, because it doesn't need more resource, schedulingMode=RESPECT_PARTITION_EXCLUSIVITY node-partition=
2017-11-12 12:41:39,852 DEBUG org.apache.hadoop.yarn.server.resourcemanager.scheduler.capacity.CapacityScheduler: nodeUpdate: hadoop-worker01:41792 clusterResources: <memory:24576, vCores:24>
2017-11-12 12:41:39,852 DEBUG org.apache.hadoop.yarn.server.resourcemanager.scheduler.capacity.CapacityScheduler: Node being looked for scheduling hadoop-worker01:41792 availableResource: <memory:8192, vCores:8>
2017-11-12 12:41:39,852 DEBUG org.apache.hadoop.yarn.server.resourcemanager.scheduler.capacity.CapacityScheduler: Trying to schedule on node: hadoop-worker01, available: <memory:8192, vCores:8>
2017-11-12 12:41:39,852 DEBUG org.apache.hadoop.yarn.server.resourcemanager.scheduler.capacity.ParentQueue: Skip this queue=root, because it doesn't need more resource, schedulingMode=RESPECT_PARTITION_EXCLUSIVITY node-partition=
2017-11-12 12:41:40,357 DEBUG org.apache.hadoop.yarn.server.resourcemanager.scheduler.capacity.CapacityScheduler: nodeUpdate: hadoop-worker03:34047 clusterResources: <memory:24576, vCores:24>
2017-11-12 12:41:40,357 DEBUG org.apache.hadoop.yarn.server.resourcemanager.scheduler.capacity.CapacityScheduler: Node being looked for scheduling hadoop-worker03:34047 availableResource: <memory:8192, vCores:8>
2017-11-12 12:41:40,357 DEBUG org.apache.hadoop.yarn.server.resourcemanager.scheduler.capacity.CapacityScheduler: Trying to schedule on node: hadoop-worker03, available: <memory:8192, vCores:8>
2017-11-12 12:41:40,357 DEBUG org.apache.hadoop.yarn.server.resourcemanager.scheduler.capacity.ParentQueue: Skip this queue=root, because it doesn't need more resource, schedulingMode=RESPECT_PARTITION_EXCLUSIVITY node-partition=
2017-11-12 12:41:40,652 DEBUG org.apache.hadoop.yarn.server.resourcemanager.scheduler.capacity.CapacityScheduler: nodeUpdate: hadoop-worker02:35444 clusterResources: <memory:24576, vCores:24>
2017-11-12 12:41:40,652 DEBUG org.apache.hadoop.yarn.server.resourcemanager.scheduler.capacity.CapacityScheduler: Node being looked for scheduling hadoop-worker02:35444 availableResource: <memory:8192, vCores:8>
2017-11-12 12:41:40,652 DEBUG org.apache.hadoop.yarn.server.resourcemanager.scheduler.capacity.CapacityScheduler: Trying to schedule on node: hadoop-worker02, available: <memory:8192, vCores:8>
2017-11-12 12:41:40,652 DEBUG org.apache.hadoop.yarn.server.resourcemanager.scheduler.capacity.ParentQueue: Skip this queue=root, because it doesn't need more resource, schedulingMode=RESPECT_PARTITION_EXCLUSIVITY node-partition=
2017-11-12 12:41:40,852 DEBUG org.apache.hadoop.yarn.server.resourcemanager.scheduler.capacity.CapacityScheduler: nodeUpdate: hadoop-worker01:41792 clusterResources: <memory:24576, vCores:24>
2017-11-12 12:41:40,852 DEBUG org.apache.hadoop.yarn.server.resourcemanager.scheduler.capacity.CapacityScheduler: Node being looked for scheduling hadoop-worker01:41792 availableResource: <memory:8192, vCores:8>
2017-11-12 12:41:40,852 DEBUG org.apache.hadoop.yarn.server.resourcemanager.scheduler.capacity.CapacityScheduler: Trying to schedule on node: hadoop-worker01, available: <memory:8192, vCores:8>
2017-11-12 12:41:40,852 DEBUG org.apache.hadoop.yarn.server.resourcemanager.scheduler.capacity.ParentQueue: Skip this queue=root, because it doesn't need more resource, schedulingMode=RESPECT_PARTITION_EXCLUSIVITY node-partition=
2017-11-12 12:41:41,358 DEBUG org.apache.hadoop.yarn.server.resourcemanager.scheduler.capacity.CapacityScheduler: nodeUpdate: hadoop-worker03:34047 clusterResources: <memory:24576, vCores:24>
2017-11-12 12:41:41,358 DEBUG org.apache.hadoop.yarn.server.resourcemanager.scheduler.capacity.CapacityScheduler: Node being looked for scheduling hadoop-worker03:34047 availableResource: <memory:8192, vCores:8>
2017-11-12 12:41:41,358 DEBUG org.apache.hadoop.yarn.server.resourcemanager.scheduler.capacity.CapacityScheduler: Trying to schedule on node: hadoop-worker03, available: <memory:8192, vCores:8>
2017-11-12 12:41:41,358 DEBUG org.apache.hadoop.yarn.server.resourcemanager.scheduler.capacity.ParentQueue: Skip this queue=root, because it doesn't need more resource, schedulingMode=RESPECT_PARTITION_EXCLUSIVITY node-partition=
2017-11-12 12:41:41,654 DEBUG org.apache.hadoop.yarn.server.resourcemanager.scheduler.capacity.CapacityScheduler: nodeUpdate: hadoop-worker02:35444 clusterResources: <memory:24576, vCores:24>
2017-11-12 12:41:41,654 DEBUG org.apache.hadoop.yarn.server.resourcemanager.scheduler.capacity.CapacityScheduler: Node being looked for scheduling hadoop-worker02:35444 availableResource: <memory:8192, vCores:8>
2017-11-12 12:41:41,654 DEBUG org.apache.hadoop.yarn.server.resourcemanager.scheduler.capacity.CapacityScheduler: Trying to schedule on node: hadoop-worker02, available: <memory:8192, vCores:8>
2017-11-12 12:41:41,654 DEBUG org.apache.hadoop.yarn.server.resourcemanager.scheduler.capacity.ParentQueue: Skip this queue=root, because it doesn't need more resource, schedulingMode=RESPECT_PARTITION_EXCLUSIVITY node-partition=
2017-11-12 12:41:41,854 DEBUG org.apache.hadoop.yarn.server.resourcemanager.scheduler.capacity.CapacityScheduler: nodeUpdate: hadoop-worker01:41792 clusterResources: <memory:24576, vCores:24>
2017-11-12 12:41:41,854 DEBUG org.apache.hadoop.yarn.server.resourcemanager.scheduler.capacity.CapacityScheduler: Node being looked for scheduling hadoop-worker01:41792 availableResource: <memory:8192, vCores:8>
2017-11-12 12:41:41,854 DEBUG org.apache.hadoop.yarn.server.resourcemanager.scheduler.capacity.CapacityScheduler: Trying to schedule on node: hadoop-worker01, available: <memory:8192, vCores:8>
2017-11-12 12:41:41,854 DEBUG org.apache.hadoop.yarn.server.resourcemanager.scheduler.capacity.ParentQueue: Skip this queue=root, because it doesn't need more resource, schedulingMode=RESPECT_PARTITION_EXCLUSIVITY node-partition=
2017-11-12 12:41:42,362 DEBUG org.apache.hadoop.yarn.server.resourcemanager.scheduler.capacity.CapacityScheduler: nodeUpdate: hadoop-worker03:34047 clusterResources: <memory:24576, vCores:24>
2017-11-12 12:41:42,362 DEBUG org.apache.hadoop.yarn.server.resourcemanager.scheduler.capacity.CapacityScheduler: Node being looked for scheduling hadoop-worker03:34047 availableResource: <memory:8192, vCores:8>
2017-11-12 12:41:42,362 DEBUG org.apache.hadoop.yarn.server.resourcemanager.scheduler.capacity.CapacityScheduler: Trying to schedule on node: hadoop-worker03, available: <memory:8192, vCores:8>
2017-11-12 12:41:42,362 DEBUG org.apache.hadoop.yarn.server.resourcemanager.scheduler.capacity.ParentQueue: Skip this queue=root, because it doesn't need more resource, schedulingMode=RESPECT_PARTITION_EXCLUSIVITY node-partition=
2017-11-12 12:41:42,655 DEBUG org.apache.hadoop.yarn.server.resourcemanager.scheduler.capacity.CapacityScheduler: nodeUpdate: hadoop-worker02:35444 clusterResources: <memory:24576, vCores:24>
2017-11-12 12:41:42,656 DEBUG org.apache.hadoop.yarn.server.resourcemanager.scheduler.capacity.CapacityScheduler: Node being looked for scheduling hadoop-worker02:35444 availableResource: <memory:8192, vCores:8>
2017-11-12 12:41:42,656 DEBUG org.apache.hadoop.yarn.server.resourcemanager.scheduler.capacity.CapacityScheduler: Trying to schedule on node: hadoop-worker02, available: <memory:8192, vCores:8>
2017-11-12 12:41:42,656 DEBUG org.apache.hadoop.yarn.server.resourcemanager.scheduler.capacity.ParentQueue: Skip this queue=root, because it doesn't need more resource, schedulingMode=RESPECT_PARTITION_EXCLUSIVITY node-partition=
2017-11-12 12:41:42,855 DEBUG org.apache.hadoop.yarn.server.resourcemanager.scheduler.capacity.CapacityScheduler: nodeUpdate: hadoop-worker01:41792 clusterResources: <memory:24576, vCores:24>
2017-11-12 12:41:42,855 DEBUG org.apache.hadoop.yarn.server.resourcemanager.scheduler.capacity.CapacityScheduler: Node being looked for scheduling hadoop-worker01:41792 availableResource: <memory:8192, vCores:8>
2017-11-12 12:41:42,855 DEBUG org.apache.hadoop.yarn.server.resourcemanager.scheduler.capacity.CapacityScheduler: Trying to schedule on node: hadoop-worker01, available: <memory:8192, vCores:8>
2017-11-12 12:41:42,855 DEBUG org.apache.hadoop.yarn.server.resourcemanager.scheduler.capacity.ParentQueue: Skip this queue=root, because it doesn't need more resource, schedulingMode=RESPECT_PARTITION_EXCLUSIVITY node-partition=
2017-11-12 12:41:43,363 DEBUG org.apache.hadoop.yarn.server.resourcemanager.scheduler.capacity.CapacityScheduler: nodeUpdate: hadoop-worker03:34047 clusterResources: <memory:24576, vCores:24>
2017-11-12 12:41:43,363 DEBUG org.apache.hadoop.yarn.server.resourcemanager.scheduler.capacity.CapacityScheduler: Node being looked for scheduling hadoop-worker03:34047 availableResource: <memory:8192, vCores:8>
2017-11-12 12:41:43,363 DEBUG org.apache.hadoop.yarn.server.resourcemanager.scheduler.capacity.CapacityScheduler: Trying to schedule on node: hadoop-worker03, available: <memory:8192, vCores:8>
2017-11-12 12:41:43,363 DEBUG org.apache.hadoop.yarn.server.resourcemanager.scheduler.capacity.ParentQueue: Skip this queue=root, because it doesn't need more resource, schedulingMode=RESPECT_PARTITION_EXCLUSIVITY node-partition=
2017-11-12 12:41:43,657 DEBUG org.apache.hadoop.yarn.server.resourcemanager.scheduler.capacity.CapacityScheduler: nodeUpdate: hadoop-worker02:35444 clusterResources: <memory:24576, vCores:24>
2017-11-12 12:41:43,657 DEBUG org.apache.hadoop.yarn.server.resourcemanager.scheduler.capacity.CapacityScheduler: Node being looked for scheduling hadoop-worker02:35444 availableResource: <memory:8192, vCores:8>
2017-11-12 12:41:43,657 DEBUG org.apache.hadoop.yarn.server.resourcemanager.scheduler.capacity.CapacityScheduler: Trying to schedule on node: hadoop-worker02, available: <memory:8192, vCores:8>
2017-11-12 12:41:43,657 DEBUG org.apache.hadoop.yarn.server.resourcemanager.scheduler.capacity.ParentQueue: Skip this queue=root, because it doesn't need more resource, schedulingMode=RESPECT_PARTITION_EXCLUSIVITY node-partition=
2017-11-12 12:41:43,857 DEBUG org.apache.hadoop.yarn.server.resourcemanager.scheduler.capacity.CapacityScheduler: nodeUpdate: hadoop-worker01:41792 clusterResources: <memory:24576, vCores:24>
2017-11-12 12:41:43,857 DEBUG org.apache.hadoop.yarn.server.resourcemanager.scheduler.capacity.CapacityScheduler: Node being looked for scheduling hadoop-worker01:41792 availableResource: <memory:8192, vCores:8>
2017-11-12 12:41:43,857 DEBUG org.apache.hadoop.yarn.server.resourcemanager.scheduler.capacity.CapacityScheduler: Trying to schedule on node: hadoop-worker01, available: <memory:8192, vCores:8>
2017-11-12 12:41:43,857 DEBUG org.apache.hadoop.yarn.server.resourcemanager.scheduler.capacity.ParentQueue: Skip this queue=root, because it doesn't need more resource, schedulingMode=RESPECT_PARTITION_EXCLUSIVITY node-partition=
2017-11-12 12:41:44,365 DEBUG org.apache.hadoop.yarn.server.resourcemanager.scheduler.capacity.CapacityScheduler: nodeUpdate: hadoop-worker03:34047 clusterResources: <memory:24576, vCores:24>
2017-11-12 12:41:44,365 DEBUG org.apache.hadoop.yarn.server.resourcemanager.scheduler.capacity.CapacityScheduler: Node being looked for scheduling hadoop-worker03:34047 availableResource: <memory:8192, vCores:8>
2017-11-12 12:41:44,365 DEBUG org.apache.hadoop.yarn.server.resourcemanager.scheduler.capacity.CapacityScheduler: Trying to schedule on node: hadoop-worker03, available: <memory:8192, vCores:8>
2017-11-12 12:41:44,365 DEBUG org.apache.hadoop.yarn.server.resourcemanager.scheduler.capacity.ParentQueue: Skip this queue=root, because it doesn't need more resource, schedulingMode=RESPECT_PARTITION_EXCLUSIVITY node-partition=
2017-11-12 12:41:44,658 DEBUG org.apache.hadoop.yarn.server.resourcemanager.scheduler.capacity.CapacityScheduler: nodeUpdate: hadoop-worker02:35444 clusterResources: <memory:24576, vCores:24>
2017-11-12 12:41:44,658 DEBUG org.apache.hadoop.yarn.server.resourcemanager.scheduler.capacity.CapacityScheduler: Node being looked for scheduling hadoop-worker02:35444 availableResource: <memory:8192, vCores:8>
2017-11-12 12:41:44,658 DEBUG org.apache.hadoop.yarn.server.resourcemanager.scheduler.capacity.CapacityScheduler: Trying to schedule on node: hadoop-worker02, available: <memory:8192, vCores:8>
2017-11-12 12:41:44,658 DEBUG org.apache.hadoop.yarn.server.resourcemanager.scheduler.capacity.ParentQueue: Skip this queue=root, because it doesn't need more resource, schedulingMode=RESPECT_PARTITION_EXCLUSIVITY node-partition=
2017-11-12 12:41:44,859 DEBUG org.apache.hadoop.yarn.server.resourcemanager.scheduler.capacity.CapacityScheduler: nodeUpdate: hadoop-worker01:41792 clusterResources: <memory:24576, vCores:24>
2017-11-12 12:41:44,859 DEBUG org.apache.hadoop.yarn.server.resourcemanager.scheduler.capacity.CapacityScheduler: Node being looked for scheduling hadoop-worker01:41792 availableResource: <memory:8192, vCores:8>
2017-11-12 12:41:44,859 DEBUG org.apache.hadoop.yarn.server.resourcemanager.scheduler.capacity.CapacityScheduler: Trying to schedule on node: hadoop-worker01, available: <memory:8192, vCores:8>
2017-11-12 12:41:44,859 DEBUG org.apache.hadoop.yarn.server.resourcemanager.scheduler.capacity.ParentQueue: Skip this queue=root, because it doesn't need more resource, schedulingMode=RESPECT_PARTITION_EXCLUSIVITY node-partition=
2017-11-12 12:41:45,366 DEBUG org.apache.hadoop.yarn.server.resourcemanager.scheduler.capacity.CapacityScheduler: nodeUpdate: hadoop-worker03:34047 clusterResources: <memory:24576, vCores:24>
2017-11-12 12:41:45,366 DEBUG org.apache.hadoop.yarn.server.resourcemanager.scheduler.capacity.CapacityScheduler: Node being looked for scheduling hadoop-worker03:34047 availableResource: <memory:8192, vCores:8>
2017-11-12 12:41:45,366 DEBUG org.apache.hadoop.yarn.server.resourcemanager.scheduler.capacity.CapacityScheduler: Trying to schedule on node: hadoop-worker03, available: <memory:8192, vCores:8>
2017-11-12 12:41:45,366 DEBUG org.apache.hadoop.yarn.server.resourcemanager.scheduler.capacity.ParentQueue: Skip this queue=root, because it doesn't need more resource, schedulingMode=RESPECT_PARTITION_EXCLUSIVITY node-partition=
2017-11-12 12:41:45,659 DEBUG org.apache.hadoop.yarn.server.resourcemanager.scheduler.capacity.CapacityScheduler: nodeUpdate: hadoop-worker02:35444 clusterResources: <memory:24576, vCores:24>
2017-11-12 12:41:45,659 DEBUG org.apache.hadoop.yarn.server.resourcemanager.scheduler.capacity.CapacityScheduler: Node being looked for scheduling hadoop-worker02:35444 availableResource: <memory:8192, vCores:8>
2017-11-12 12:41:45,659 DEBUG org.apache.hadoop.yarn.server.resourcemanager.scheduler.capacity.CapacityScheduler: Trying to schedule on node: hadoop-worker02, available: <memory:8192, vCores:8>
2017-11-12 12:41:45,659 DEBUG org.apache.hadoop.yarn.server.resourcemanager.scheduler.capacity.ParentQueue: Skip this queue=root, because it doesn't need more resource, schedulingMode=RESPECT_PARTITION_EXCLUSIVITY node-partition=
2017-11-12 12:41:45,861 DEBUG org.apache.hadoop.yarn.server.resourcemanager.scheduler.capacity.CapacityScheduler: nodeUpdate: hadoop-worker01:41792 clusterResources: <memory:24576, vCores:24>
2017-11-12 12:41:45,861 DEBUG org.apache.hadoop.yarn.server.resourcemanager.scheduler.capacity.CapacityScheduler: Node being looked for scheduling hadoop-worker01:41792 availableResource: <memory:8192, vCores:8>
2017-11-12 12:41:45,861 DEBUG org.apache.hadoop.yarn.server.resourcemanager.scheduler.capacity.CapacityScheduler: Trying to schedule on node: hadoop-worker01, available: <memory:8192, vCores:8>
2017-11-12 12:41:45,861 DEBUG org.apache.hadoop.yarn.server.resourcemanager.scheduler.capacity.ParentQueue: Skip this queue=root, because it doesn't need more resource, schedulingMode=RESPECT_PARTITION_EXCLUSIVITY node-partition=
2017-11-12 12:41:46,367 DEBUG org.apache.hadoop.yarn.server.resourcemanager.scheduler.capacity.CapacityScheduler: nodeUpdate: hadoop-worker03:34047 clusterResources: <memory:24576, vCores:24>
2017-11-12 12:41:46,368 DEBUG org.apache.hadoop.yarn.server.resourcemanager.scheduler.capacity.CapacityScheduler: Node being looked for scheduling hadoop-worker03:34047 availableResource: <memory:8192, vCores:8>
2017-11-12 12:41:46,368 DEBUG org.apache.hadoop.yarn.server.resourcemanager.scheduler.capacity.CapacityScheduler: Trying to schedule on node: hadoop-worker03, available: <memory:8192, vCores:8>
2017-11-12 12:41:46,368 DEBUG org.apache.hadoop.yarn.server.resourcemanager.scheduler.capacity.ParentQueue: Skip this queue=root, because it doesn't need more resource, schedulingMode=RESPECT_PARTITION_EXCLUSIVITY node-partition=
2017-11-12 12:41:46,661 DEBUG org.apache.hadoop.yarn.server.resourcemanager.scheduler.capacity.CapacityScheduler: nodeUpdate: hadoop-worker02:35444 clusterResources: <memory:24576, vCores:24>
2017-11-12 12:41:46,661 DEBUG org.apache.hadoop.yarn.server.resourcemanager.scheduler.capacity.CapacityScheduler: Node being looked for scheduling hadoop-worker02:35444 availableResource: <memory:8192, vCores:8>
2017-11-12 12:41:46,661 DEBUG org.apache.hadoop.yarn.server.resourcemanager.scheduler.capacity.CapacityScheduler: Trying to schedule on node: hadoop-worker02, available: <memory:8192, vCores:8>
2017-11-12 12:41:46,661 DEBUG org.apache.hadoop.yarn.server.resourcemanager.scheduler.capacity.ParentQueue: Skip this queue=root, because it doesn't need more resource, schedulingMode=RESPECT_PARTITION_EXCLUSIVITY node-partition=
2017-11-12 12:41:46,862 DEBUG org.apache.hadoop.yarn.server.resourcemanager.scheduler.capacity.CapacityScheduler: nodeUpdate: hadoop-worker01:41792 clusterResources: <memory:24576, vCores:24>
2017-11-12 12:41:46,863 DEBUG org.apache.hadoop.yarn.server.resourcemanager.scheduler.capacity.CapacityScheduler: Node being looked for scheduling hadoop-worker01:41792 availableResource: <memory:8192, vCores:8>
2017-11-12 12:41:46,863 DEBUG org.apache.hadoop.yarn.server.resourcemanager.scheduler.capacity.CapacityScheduler: Trying to schedule on node: hadoop-worker01, available: <memory:8192, vCores:8>
2017-11-12 12:41:46,863 DEBUG org.apache.hadoop.yarn.server.resourcemanager.scheduler.capacity.ParentQueue: Skip this queue=root, because it doesn't need more resource, schedulingMode=RESPECT_PARTITION_EXCLUSIVITY node-partition=
2017-11-12 12:41:47,373 DEBUG org.apache.hadoop.yarn.server.resourcemanager.scheduler.capacity.CapacityScheduler: nodeUpdate: hadoop-worker03:34047 clusterResources: <memory:24576, vCores:24>
2017-11-12 12:41:47,373 DEBUG org.apache.hadoop.yarn.server.resourcemanager.scheduler.capacity.CapacityScheduler: Node being looked for scheduling hadoop-worker03:34047 availableResource: <memory:8192, vCores:8>
2017-11-12 12:41:47,373 DEBUG org.apache.hadoop.yarn.server.resourcemanager.scheduler.capacity.CapacityScheduler: Trying to schedule on node: hadoop-worker03, available: <memory:8192, vCores:8>
2017-11-12 12:41:47,373 DEBUG org.apache.hadoop.yarn.server.resourcemanager.scheduler.capacity.ParentQueue: Skip this queue=root, because it doesn't need more resource, schedulingMode=RESPECT_PARTITION_EXCLUSIVITY node-partition=
2017-11-12 12:41:47,662 DEBUG org.apache.hadoop.yarn.server.resourcemanager.scheduler.capacity.CapacityScheduler: nodeUpdate: hadoop-worker02:35444 clusterResources: <memory:24576, vCores:24>
2017-11-12 12:41:47,662 DEBUG org.apache.hadoop.yarn.server.resourcemanager.scheduler.capacity.CapacityScheduler: Node being looked for scheduling hadoop-worker02:35444 availableResource: <memory:8192, vCores:8>
2017-11-12 12:41:47,663 DEBUG org.apache.hadoop.yarn.server.resourcemanager.scheduler.capacity.CapacityScheduler: Trying to schedule on node: hadoop-worker02, available: <memory:8192, vCores:8>
2017-11-12 12:41:47,663 DEBUG org.apache.hadoop.yarn.server.resourcemanager.scheduler.capacity.ParentQueue: Skip this queue=root, because it doesn't need more resource, schedulingMode=RESPECT_PARTITION_EXCLUSIVITY node-partition=
2017-11-12 12:41:47,864 DEBUG org.apache.hadoop.yarn.server.resourcemanager.scheduler.capacity.CapacityScheduler: nodeUpdate: hadoop-worker01:41792 clusterResources: <memory:24576, vCores:24>
2017-11-12 12:41:47,864 DEBUG org.apache.hadoop.yarn.server.resourcemanager.scheduler.capacity.CapacityScheduler: Node being looked for scheduling hadoop-worker01:41792 availableResource: <memory:8192, vCores:8>
2017-11-12 12:41:47,864 DEBUG org.apache.hadoop.yarn.server.resourcemanager.scheduler.capacity.CapacityScheduler: Trying to schedule on node: hadoop-worker01, available: <memory:8192, vCores:8>
2017-11-12 12:41:47,864 DEBUG org.apache.hadoop.yarn.server.resourcemanager.scheduler.capacity.ParentQueue: Skip this queue=root, because it doesn't need more resource, schedulingMode=RESPECT_PARTITION_EXCLUSIVITY node-partition=
2017-11-12 12:41:48,374 DEBUG org.apache.hadoop.yarn.server.resourcemanager.scheduler.capacity.CapacityScheduler: nodeUpdate: hadoop-worker03:34047 clusterResources: <memory:24576, vCores:24>
2017-11-12 12:41:48,374 DEBUG org.apache.hadoop.yarn.server.resourcemanager.scheduler.capacity.CapacityScheduler: Node being looked for scheduling hadoop-worker03:34047 availableResource: <memory:8192, vCores:8>
2017-11-12 12:41:48,374 DEBUG org.apache.hadoop.yarn.server.resourcemanager.scheduler.capacity.CapacityScheduler: Trying to schedule on node: hadoop-worker03, available: <memory:8192, vCores:8>
2017-11-12 12:41:48,374 DEBUG org.apache.hadoop.yarn.server.resourcemanager.scheduler.capacity.ParentQueue: Skip this queue=root, because it doesn't need more resource, schedulingMode=RESPECT_PARTITION_EXCLUSIVITY node-partition=
2017-11-12 12:41:48,666 DEBUG org.apache.hadoop.yarn.server.resourcemanager.scheduler.capacity.CapacityScheduler: nodeUpdate: hadoop-worker02:35444 clusterResources: <memory:24576, vCores:24>
2017-11-12 12:41:48,666 DEBUG org.apache.hadoop.yarn.server.resourcemanager.scheduler.capacity.CapacityScheduler: Node being looked for scheduling hadoop-worker02:35444 availableResource: <memory:8192, vCores:8>
2017-11-12 12:41:48,666 DEBUG org.apache.hadoop.yarn.server.resourcemanager.scheduler.capacity.CapacityScheduler: Trying to schedule on node: hadoop-worker02, available: <memory:8192, vCores:8>
2017-11-12 12:41:48,666 DEBUG org.apache.hadoop.yarn.server.resourcemanager.scheduler.capacity.ParentQueue: Skip this queue=root, because it doesn't need more resource, schedulingMode=RESPECT_PARTITION_EXCLUSIVITY node-partition=
2017-11-12 12:41:48,866 DEBUG org.apache.hadoop.yarn.server.resourcemanager.scheduler.capacity.CapacityScheduler: nodeUpdate: hadoop-worker01:41792 clusterResources: <memory:24576, vCores:24>
2017-11-12 12:41:48,866 DEBUG org.apache.hadoop.yarn.server.resourcemanager.scheduler.capacity.CapacityScheduler: Node being looked for scheduling hadoop-worker01:41792 availableResource: <memory:8192, vCores:8>
2017-11-12 12:41:48,866 DEBUG org.apache.hadoop.yarn.server.resourcemanager.scheduler.capacity.CapacityScheduler: Trying to schedule on node: hadoop-worker01, available: <memory:8192, vCores:8>
2017-11-12 12:41:48,866 DEBUG org.apache.hadoop.yarn.server.resourcemanager.scheduler.capacity.ParentQueue: Skip this queue=root, because it doesn't need more resource, schedulingMode=RESPECT_PARTITION_EXCLUSIVITY node-partition=
2017-11-12 12:41:49,375 DEBUG org.apache.hadoop.yarn.server.resourcemanager.scheduler.capacity.CapacityScheduler: nodeUpdate: hadoop-worker03:34047 clusterResources: <memory:24576, vCores:24>
2017-11-12 12:41:49,375 DEBUG org.apache.hadoop.yarn.server.resourcemanager.scheduler.capacity.CapacityScheduler: Node being looked for scheduling hadoop-worker03:34047 availableResource: <memory:8192, vCores:8>
2017-11-12 12:41:49,375 DEBUG org.apache.hadoop.yarn.server.resourcemanager.scheduler.capacity.CapacityScheduler: Trying to schedule on node: hadoop-worker03, available: <memory:8192, vCores:8>
2017-11-12 12:41:49,375 DEBUG org.apache.hadoop.yarn.server.resourcemanager.scheduler.capacity.ParentQueue: Skip this queue=root, because it doesn't need more resource, schedulingMode=RESPECT_PARTITION_EXCLUSIVITY node-partition=
2017-11-12 12:41:49,668 DEBUG org.apache.hadoop.yarn.server.resourcemanager.scheduler.capacity.CapacityScheduler: nodeUpdate: hadoop-worker02:35444 clusterResources: <memory:24576, vCores:24>
2017-11-12 12:41:49,668 DEBUG org.apache.hadoop.yarn.server.resourcemanager.scheduler.capacity.CapacityScheduler: Node being looked for scheduling hadoop-worker02:35444 availableResource: <memory:8192, vCores:8>
2017-11-12 12:41:49,668 DEBUG org.apache.hadoop.yarn.server.resourcemanager.scheduler.capacity.CapacityScheduler: Trying to schedule on node: hadoop-worker02, available: <memory:8192, vCores:8>
2017-11-12 12:41:49,668 DEBUG org.apache.hadoop.yarn.server.resourcemanager.scheduler.capacity.ParentQueue: Skip this queue=root, because it doesn't need more resource, schedulingMode=RESPECT_PARTITION_EXCLUSIVITY node-partition=
2017-11-12 12:41:49,867 DEBUG org.apache.hadoop.yarn.server.resourcemanager.scheduler.capacity.CapacityScheduler: nodeUpdate: hadoop-worker01:41792 clusterResources: <memory:24576, vCores:24>
2017-11-12 12:41:49,868 DEBUG org.apache.hadoop.yarn.server.resourcemanager.scheduler.capacity.CapacityScheduler: Node being looked for scheduling hadoop-worker01:41792 availableResource: <memory:8192, vCores:8>
2017-11-12 12:41:49,868 DEBUG org.apache.hadoop.yarn.server.resourcemanager.scheduler.capacity.CapacityScheduler: Trying to schedule on node: hadoop-worker01, available: <memory:8192, vCores:8>
2017-11-12 12:41:49,868 DEBUG org.apache.hadoop.yarn.server.resourcemanager.scheduler.capacity.ParentQueue: Skip this queue=root, because it doesn't need more resource, schedulingMode=RESPECT_PARTITION_EXCLUSIVITY node-partition=
2017-11-12 12:41:50,376 DEBUG org.apache.hadoop.yarn.server.resourcemanager.scheduler.capacity.CapacityScheduler: nodeUpdate: hadoop-worker03:34047 clusterResources: <memory:24576, vCores:24>
2017-11-12 12:41:50,376 DEBUG org.apache.hadoop.yarn.server.resourcemanager.scheduler.capacity.CapacityScheduler: Node being looked for scheduling hadoop-worker03:34047 availableResource: <memory:8192, vCores:8>
2017-11-12 12:41:50,376 DEBUG org.apache.hadoop.yarn.server.resourcemanager.scheduler.capacity.CapacityScheduler: Trying to schedule on node: hadoop-worker03, available: <memory:8192, vCores:8>
2017-11-12 12:41:50,377 DEBUG org.apache.hadoop.yarn.server.resourcemanager.scheduler.capacity.ParentQueue: Skip this queue=root, because it doesn't need more resource, schedulingMode=RESPECT_PARTITION_EXCLUSIVITY node-partition=
2017-11-12 12:41:50,669 DEBUG org.apache.hadoop.yarn.server.resourcemanager.scheduler.capacity.CapacityScheduler: nodeUpdate: hadoop-worker02:35444 clusterResources: <memory:24576, vCores:24>
2017-11-12 12:41:50,669 DEBUG org.apache.hadoop.yarn.server.resourcemanager.scheduler.capacity.CapacityScheduler: Node being looked for scheduling hadoop-worker02:35444 availableResource: <memory:8192, vCores:8>
2017-11-12 12:41:50,669 DEBUG org.apache.hadoop.yarn.server.resourcemanager.scheduler.capacity.CapacityScheduler: Trying to schedule on node: hadoop-worker02, available: <memory:8192, vCores:8>
2017-11-12 12:41:50,669 DEBUG org.apache.hadoop.yarn.server.resourcemanager.scheduler.capacity.ParentQueue: Skip this queue=root, because it doesn't need more resource, schedulingMode=RESPECT_PARTITION_EXCLUSIVITY node-partition=
2017-11-12 12:41:50,870 DEBUG org.apache.hadoop.yarn.server.resourcemanager.scheduler.capacity.CapacityScheduler: nodeUpdate: hadoop-worker01:41792 clusterResources: <memory:24576, vCores:24>
2017-11-12 12:41:50,870 DEBUG org.apache.hadoop.yarn.server.resourcemanager.scheduler.capacity.CapacityScheduler: Node being looked for scheduling hadoop-worker01:41792 availableResource: <memory:8192, vCores:8>
2017-11-12 12:41:50,870 DEBUG org.apache.hadoop.yarn.server.resourcemanager.scheduler.capacity.CapacityScheduler: Trying to schedule on node: hadoop-worker01, available: <memory:8192, vCores:8>
2017-11-12 12:41:50,870 DEBUG org.apache.hadoop.yarn.server.resourcemanager.scheduler.capacity.ParentQueue: Skip this queue=root, because it doesn't need more resource, schedulingMode=RESPECT_PARTITION_EXCLUSIVITY node-partition=
2017-11-12 12:41:51,378 DEBUG org.apache.hadoop.yarn.server.resourcemanager.scheduler.capacity.CapacityScheduler: nodeUpdate: hadoop-worker03:34047 clusterResources: <memory:24576, vCores:24>
2017-11-12 12:41:51,378 DEBUG org.apache.hadoop.yarn.server.resourcemanager.scheduler.capacity.CapacityScheduler: Node being looked for scheduling hadoop-worker03:34047 availableResource: <memory:8192, vCores:8>
2017-11-12 12:41:51,378 DEBUG org.apache.hadoop.yarn.server.resourcemanager.scheduler.capacity.CapacityScheduler: Trying to schedule on node: hadoop-worker03, available: <memory:8192, vCores:8>
2017-11-12 12:41:51,378 DEBUG org.apache.hadoop.yarn.server.resourcemanager.scheduler.capacity.ParentQueue: Skip this queue=root, because it doesn't need more resource, schedulingMode=RESPECT_PARTITION_EXCLUSIVITY node-partition=
2017-11-12 12:41:51,671 DEBUG org.apache.hadoop.yarn.server.resourcemanager.scheduler.capacity.CapacityScheduler: nodeUpdate: hadoop-worker02:35444 clusterResources: <memory:24576, vCores:24>
2017-11-12 12:41:51,671 DEBUG org.apache.hadoop.yarn.server.resourcemanager.scheduler.capacity.CapacityScheduler: Node being looked for scheduling hadoop-worker02:35444 availableResource: <memory:8192, vCores:8>
2017-11-12 12:41:51,671 DEBUG org.apache.hadoop.yarn.server.resourcemanager.scheduler.capacity.CapacityScheduler: Trying to schedule on node: hadoop-worker02, available: <memory:8192, vCores:8>
2017-11-12 12:41:51,671 DEBUG org.apache.hadoop.yarn.server.resourcemanager.scheduler.capacity.ParentQueue: Skip this queue=root, because it doesn't need more resource, schedulingMode=RESPECT_PARTITION_EXCLUSIVITY node-partition=
2017-11-12 12:41:51,870 DEBUG org.apache.hadoop.yarn.server.resourcemanager.scheduler.capacity.CapacityScheduler: nodeUpdate: hadoop-worker01:41792 clusterResources: <memory:24576, vCores:24>
2017-11-12 12:41:51,870 DEBUG org.apache.hadoop.yarn.server.resourcemanager.scheduler.capacity.CapacityScheduler: Node being looked for scheduling hadoop-worker01:41792 availableResource: <memory:8192, vCores:8>
2017-11-12 12:41:51,870 DEBUG org.apache.hadoop.yarn.server.resourcemanager.scheduler.capacity.CapacityScheduler: Trying to schedule on node: hadoop-worker01, available: <memory:8192, vCores:8>
2017-11-12 12:41:51,870 DEBUG org.apache.hadoop.yarn.server.resourcemanager.scheduler.capacity.ParentQueue: Skip this queue=root, because it doesn't need more resource, schedulingMode=RESPECT_PARTITION_EXCLUSIVITY node-partition=
2017-11-12 12:41:52,381 DEBUG org.apache.hadoop.yarn.server.resourcemanager.scheduler.capacity.CapacityScheduler: nodeUpdate: hadoop-worker03:34047 clusterResources: <memory:24576, vCores:24>
2017-11-12 12:41:52,381 DEBUG org.apache.hadoop.yarn.server.resourcemanager.scheduler.capacity.CapacityScheduler: Node being looked for scheduling hadoop-worker03:34047 availableResource: <memory:8192, vCores:8>
2017-11-12 12:41:52,381 DEBUG org.apache.hadoop.yarn.server.resourcemanager.scheduler.capacity.CapacityScheduler: Trying to schedule on node: hadoop-worker03, available: <memory:8192, vCores:8>
2017-11-12 12:41:52,381 DEBUG org.apache.hadoop.yarn.server.resourcemanager.scheduler.capacity.ParentQueue: Skip this queue=root, because it doesn't need more resource, schedulingMode=RESPECT_PARTITION_EXCLUSIVITY node-partition=
2017-11-12 12:41:52,673 DEBUG org.apache.hadoop.yarn.server.resourcemanager.scheduler.capacity.CapacityScheduler: nodeUpdate: hadoop-worker02:35444 clusterResources: <memory:24576, vCores:24>
2017-11-12 12:41:52,673 DEBUG org.apache.hadoop.yarn.server.resourcemanager.scheduler.capacity.CapacityScheduler: Node being looked for scheduling hadoop-worker02:35444 availableResource: <memory:8192, vCores:8>
2017-11-12 12:41:52,673 DEBUG org.apache.hadoop.yarn.server.resourcemanager.scheduler.capacity.CapacityScheduler: Trying to schedule on node: hadoop-worker02, available: <memory:8192, vCores:8>
2017-11-12 12:41:52,673 DEBUG org.apache.hadoop.yarn.server.resourcemanager.scheduler.capacity.ParentQueue: Skip this queue=root, because it doesn't need more resource, schedulingMode=RESPECT_PARTITION_EXCLUSIVITY node-partition=
2017-11-12 12:41:52,871 DEBUG org.apache.hadoop.yarn.server.resourcemanager.scheduler.capacity.CapacityScheduler: nodeUpdate: hadoop-worker01:41792 clusterResources: <memory:24576, vCores:24>
2017-11-12 12:41:52,871 DEBUG org.apache.hadoop.yarn.server.resourcemanager.scheduler.capacity.CapacityScheduler: Node being looked for scheduling hadoop-worker01:41792 availableResource: <memory:8192, vCores:8>
2017-11-12 12:41:52,871 DEBUG org.apache.hadoop.yarn.server.resourcemanager.scheduler.capacity.CapacityScheduler: Trying to schedule on node: hadoop-worker01, available: <memory:8192, vCores:8>
2017-11-12 12:41:52,871 DEBUG org.apache.hadoop.yarn.server.resourcemanager.scheduler.capacity.ParentQueue: Skip this queue=root, because it doesn't need more resource, schedulingMode=RESPECT_PARTITION_EXCLUSIVITY node-partition=
2017-11-12 12:41:53,382 DEBUG org.apache.hadoop.yarn.server.resourcemanager.scheduler.capacity.CapacityScheduler: nodeUpdate: hadoop-worker03:34047 clusterResources: <memory:24576, vCores:24>
2017-11-12 12:41:53,382 DEBUG org.apache.hadoop.yarn.server.resourcemanager.scheduler.capacity.CapacityScheduler: Node being looked for scheduling hadoop-worker03:34047 availableResource: <memory:8192, vCores:8>
2017-11-12 12:41:53,382 DEBUG org.apache.hadoop.yarn.server.resourcemanager.scheduler.capacity.CapacityScheduler: Trying to schedule on node: hadoop-worker03, available: <memory:8192, vCores:8>
2017-11-12 12:41:53,382 DEBUG org.apache.hadoop.yarn.server.resourcemanager.scheduler.capacity.ParentQueue: Skip this queue=root, because it doesn't need more resource, schedulingMode=RESPECT_PARTITION_EXCLUSIVITY node-partition=
2017-11-12 12:41:53,674 DEBUG org.apache.hadoop.yarn.server.resourcemanager.scheduler.capacity.CapacityScheduler: nodeUpdate: hadoop-worker02:35444 clusterResources: <memory:24576, vCores:24>
2017-11-12 12:41:53,674 DEBUG org.apache.hadoop.yarn.server.resourcemanager.scheduler.capacity.CapacityScheduler: Node being looked for scheduling hadoop-worker02:35444 availableResource: <memory:8192, vCores:8>
2017-11-12 12:41:53,674 DEBUG org.apache.hadoop.yarn.server.resourcemanager.scheduler.capacity.CapacityScheduler: Trying to schedule on node: hadoop-worker02, available: <memory:8192, vCores:8>
2017-11-12 12:41:53,674 DEBUG org.apache.hadoop.yarn.server.resourcemanager.scheduler.capacity.ParentQueue: Skip this queue=root, because it doesn't need more resource, schedulingMode=RESPECT_PARTITION_EXCLUSIVITY node-partition=
2017-11-12 12:41:53,879 DEBUG org.apache.hadoop.yarn.server.resourcemanager.scheduler.capacity.CapacityScheduler: nodeUpdate: hadoop-worker01:41792 clusterResources: <memory:24576, vCores:24>
2017-11-12 12:41:53,879 DEBUG org.apache.hadoop.yarn.server.resourcemanager.scheduler.capacity.CapacityScheduler: Node being looked for scheduling hadoop-worker01:41792 availableResource: <memory:8192, vCores:8>
2017-11-12 12:41:53,879 DEBUG org.apache.hadoop.yarn.server.resourcemanager.scheduler.capacity.CapacityScheduler: Trying to schedule on node: hadoop-worker01, available: <memory:8192, vCores:8>
2017-11-12 12:41:53,879 DEBUG org.apache.hadoop.yarn.server.resourcemanager.scheduler.capacity.ParentQueue: Skip this queue=root, because it doesn't need more resource, schedulingMode=RESPECT_PARTITION_EXCLUSIVITY node-partition=
2017-11-12 12:41:54,383 DEBUG org.apache.hadoop.yarn.server.resourcemanager.scheduler.capacity.CapacityScheduler: nodeUpdate: hadoop-worker03:34047 clusterResources: <memory:24576, vCores:24>
2017-11-12 12:41:54,383 DEBUG org.apache.hadoop.yarn.server.resourcemanager.scheduler.capacity.CapacityScheduler: Node being looked for scheduling hadoop-worker03:34047 availableResource: <memory:8192, vCores:8>
2017-11-12 12:41:54,383 DEBUG org.apache.hadoop.yarn.server.resourcemanager.scheduler.capacity.CapacityScheduler: Trying to schedule on node: hadoop-worker03, available: <memory:8192, vCores:8>
2017-11-12 12:41:54,383 DEBUG org.apache.hadoop.yarn.server.resourcemanager.scheduler.capacity.ParentQueue: Skip this queue=root, because it doesn't need more resource, schedulingMode=RESPECT_PARTITION_EXCLUSIVITY node-partition=
2017-11-12 12:41:54,676 DEBUG org.apache.hadoop.yarn.server.resourcemanager.scheduler.capacity.CapacityScheduler: nodeUpdate: hadoop-worker02:35444 clusterResources: <memory:24576, vCores:24>
2017-11-12 12:41:54,676 DEBUG org.apache.hadoop.yarn.server.resourcemanager.scheduler.capacity.CapacityScheduler: Node being looked for scheduling hadoop-worker02:35444 availableResource: <memory:8192, vCores:8>
2017-11-12 12:41:54,676 DEBUG org.apache.hadoop.yarn.server.resourcemanager.scheduler.capacity.CapacityScheduler: Trying to schedule on node: hadoop-worker02, available: <memory:8192, vCores:8>
2017-11-12 12:41:54,676 DEBUG org.apache.hadoop.yarn.server.resourcemanager.scheduler.capacity.ParentQueue: Skip this queue=root, because it doesn't need more resource, schedulingMode=RESPECT_PARTITION_EXCLUSIVITY node-partition=
2017-11-12 12:41:54,880 DEBUG org.apache.hadoop.yarn.server.resourcemanager.scheduler.capacity.CapacityScheduler: nodeUpdate: hadoop-worker01:41792 clusterResources: <memory:24576, vCores:24>
2017-11-12 12:41:54,880 DEBUG org.apache.hadoop.yarn.server.resourcemanager.scheduler.capacity.CapacityScheduler: Node being looked for scheduling hadoop-worker01:41792 availableResource: <memory:8192, vCores:8>
2017-11-12 12:41:54,880 DEBUG org.apache.hadoop.yarn.server.resourcemanager.scheduler.capacity.CapacityScheduler: Trying to schedule on node: hadoop-worker01, available: <memory:8192, vCores:8>
2017-11-12 12:41:54,880 DEBUG org.apache.hadoop.yarn.server.resourcemanager.scheduler.capacity.ParentQueue: Skip this queue=root, because it doesn't need more resource, schedulingMode=RESPECT_PARTITION_EXCLUSIVITY node-partition=
2017-11-12 12:41:55,384 DEBUG org.apache.hadoop.yarn.server.resourcemanager.scheduler.capacity.CapacityScheduler: nodeUpdate: hadoop-worker03:34047 clusterResources: <memory:24576, vCores:24>
2017-11-12 12:41:55,384 DEBUG org.apache.hadoop.yarn.server.resourcemanager.scheduler.capacity.CapacityScheduler: Node being looked for scheduling hadoop-worker03:34047 availableResource: <memory:8192, vCores:8>
2017-11-12 12:41:55,385 DEBUG org.apache.hadoop.yarn.server.resourcemanager.scheduler.capacity.CapacityScheduler: Trying to schedule on node: hadoop-worker03, available: <memory:8192, vCores:8>
2017-11-12 12:41:55,385 DEBUG org.apache.hadoop.yarn.server.resourcemanager.scheduler.capacity.ParentQueue: Skip this queue=root, because it doesn't need more resource, schedulingMode=RESPECT_PARTITION_EXCLUSIVITY node-partition=
2017-11-12 12:41:55,678 DEBUG org.apache.hadoop.yarn.server.resourcemanager.scheduler.capacity.CapacityScheduler: nodeUpdate: hadoop-worker02:35444 clusterResources: <memory:24576, vCores:24>
2017-11-12 12:41:55,679 DEBUG org.apache.hadoop.yarn.server.resourcemanager.scheduler.capacity.CapacityScheduler: Node being looked for scheduling hadoop-worker02:35444 availableResource: <memory:8192, vCores:8>
2017-11-12 12:41:55,679 DEBUG org.apache.hadoop.yarn.server.resourcemanager.scheduler.capacity.CapacityScheduler: Trying to schedule on node: hadoop-worker02, available: <memory:8192, vCores:8>
2017-11-12 12:41:55,679 DEBUG org.apache.hadoop.yarn.server.resourcemanager.scheduler.capacity.ParentQueue: Skip this queue=root, because it doesn't need more resource, schedulingMode=RESPECT_PARTITION_EXCLUSIVITY node-partition=
2017-11-12 12:41:55,882 DEBUG org.apache.hadoop.yarn.server.resourcemanager.scheduler.capacity.CapacityScheduler: nodeUpdate: hadoop-worker01:41792 clusterResources: <memory:24576, vCores:24>
2017-11-12 12:41:55,882 DEBUG org.apache.hadoop.yarn.server.resourcemanager.scheduler.capacity.CapacityScheduler: Node being looked for scheduling hadoop-worker01:41792 availableResource: <memory:8192, vCores:8>
2017-11-12 12:41:55,882 DEBUG org.apache.hadoop.yarn.server.resourcemanager.scheduler.capacity.CapacityScheduler: Trying to schedule on node: hadoop-worker01, available: <memory:8192, vCores:8>
2017-11-12 12:41:55,882 DEBUG org.apache.hadoop.yarn.server.resourcemanager.scheduler.capacity.ParentQueue: Skip this queue=root, because it doesn't need more resource, schedulingMode=RESPECT_PARTITION_EXCLUSIVITY node-partition=
2017-11-12 12:41:56,386 DEBUG org.apache.hadoop.yarn.server.resourcemanager.scheduler.capacity.CapacityScheduler: nodeUpdate: hadoop-worker03:34047 clusterResources: <memory:24576, vCores:24>
2017-11-12 12:41:56,386 DEBUG org.apache.hadoop.yarn.server.resourcemanager.scheduler.capacity.CapacityScheduler: Node being looked for scheduling hadoop-worker03:34047 availableResource: <memory:8192, vCores:8>
2017-11-12 12:41:56,386 DEBUG org.apache.hadoop.yarn.server.resourcemanager.scheduler.capacity.CapacityScheduler: Trying to schedule on node: hadoop-worker03, available: <memory:8192, vCores:8>
2017-11-12 12:41:56,386 DEBUG org.apache.hadoop.yarn.server.resourcemanager.scheduler.capacity.ParentQueue: Skip this queue=root, because it doesn't need more resource, schedulingMode=RESPECT_PARTITION_EXCLUSIVITY node-partition=
2017-11-12 12:41:56,680 DEBUG org.apache.hadoop.yarn.server.resourcemanager.scheduler.capacity.CapacityScheduler: nodeUpdate: hadoop-worker02:35444 clusterResources: <memory:24576, vCores:24>
2017-11-12 12:41:56,680 DEBUG org.apache.hadoop.yarn.server.resourcemanager.scheduler.capacity.CapacityScheduler: Node being looked for scheduling hadoop-worker02:35444 availableResource: <memory:8192, vCores:8>
2017-11-12 12:41:56,680 DEBUG org.apache.hadoop.yarn.server.resourcemanager.scheduler.capacity.CapacityScheduler: Trying to schedule on node: hadoop-worker02, available: <memory:8192, vCores:8>
2017-11-12 12:41:56,680 DEBUG org.apache.hadoop.yarn.server.resourcemanager.scheduler.capacity.ParentQueue: Skip this queue=root, because it doesn't need more resource, schedulingMode=RESPECT_PARTITION_EXCLUSIVITY node-partition=
2017-11-12 12:41:56,883 DEBUG org.apache.hadoop.yarn.server.resourcemanager.scheduler.capacity.CapacityScheduler: nodeUpdate: hadoop-worker01:41792 clusterResources: <memory:24576, vCores:24>
2017-11-12 12:41:56,883 DEBUG org.apache.hadoop.yarn.server.resourcemanager.scheduler.capacity.CapacityScheduler: Node being looked for scheduling hadoop-worker01:41792 availableResource: <memory:8192, vCores:8>
2017-11-12 12:41:56,883 DEBUG org.apache.hadoop.yarn.server.resourcemanager.scheduler.capacity.CapacityScheduler: Trying to schedule on node: hadoop-worker01, available: <memory:8192, vCores:8>
2017-11-12 12:41:56,883 DEBUG org.apache.hadoop.yarn.server.resourcemanager.scheduler.capacity.ParentQueue: Skip this queue=root, because it doesn't need more resource, schedulingMode=RESPECT_PARTITION_EXCLUSIVITY node-partition=
2017-11-12 12:41:57,387 DEBUG org.apache.hadoop.yarn.server.resourcemanager.scheduler.capacity.CapacityScheduler: nodeUpdate: hadoop-worker03:34047 clusterResources: <memory:24576, vCores:24>
2017-11-12 12:41:57,388 DEBUG org.apache.hadoop.yarn.server.resourcemanager.scheduler.capacity.CapacityScheduler: Node being looked for scheduling hadoop-worker03:34047 availableResource: <memory:8192, vCores:8>
2017-11-12 12:41:57,388 DEBUG org.apache.hadoop.yarn.server.resourcemanager.scheduler.capacity.CapacityScheduler: Trying to schedule on node: hadoop-worker03, available: <memory:8192, vCores:8>
2017-11-12 12:41:57,388 DEBUG org.apache.hadoop.yarn.server.resourcemanager.scheduler.capacity.ParentQueue: Skip this queue=root, because it doesn't need more resource, schedulingMode=RESPECT_PARTITION_EXCLUSIVITY node-partition=
2017-11-12 12:41:57,682 DEBUG org.apache.hadoop.yarn.server.resourcemanager.scheduler.capacity.CapacityScheduler: nodeUpdate: hadoop-worker02:35444 clusterResources: <memory:24576, vCores:24>
2017-11-12 12:41:57,682 DEBUG org.apache.hadoop.yarn.server.resourcemanager.scheduler.capacity.CapacityScheduler: Node being looked for scheduling hadoop-worker02:35444 availableResource: <memory:8192, vCores:8>
2017-11-12 12:41:57,682 DEBUG org.apache.hadoop.yarn.server.resourcemanager.scheduler.capacity.CapacityScheduler: Trying to schedule on node: hadoop-worker02, available: <memory:8192, vCores:8>
2017-11-12 12:41:57,682 DEBUG org.apache.hadoop.yarn.server.resourcemanager.scheduler.capacity.ParentQueue: Skip this queue=root, because it doesn't need more resource, schedulingMode=RESPECT_PARTITION_EXCLUSIVITY node-partition=
2017-11-12 12:41:57,885 DEBUG org.apache.hadoop.yarn.server.resourcemanager.scheduler.capacity.CapacityScheduler: nodeUpdate: hadoop-worker01:41792 clusterResources: <memory:24576, vCores:24>
2017-11-12 12:41:57,885 DEBUG org.apache.hadoop.yarn.server.resourcemanager.scheduler.capacity.CapacityScheduler: Node being looked for scheduling hadoop-worker01:41792 availableResource: <memory:8192, vCores:8>
2017-11-12 12:41:57,885 DEBUG org.apache.hadoop.yarn.server.resourcemanager.scheduler.capacity.CapacityScheduler: Trying to schedule on node: hadoop-worker01, available: <memory:8192, vCores:8>
2017-11-12 12:41:57,885 DEBUG org.apache.hadoop.yarn.server.resourcemanager.scheduler.capacity.ParentQueue: Skip this queue=root, because it doesn't need more resource, schedulingMode=RESPECT_PARTITION_EXCLUSIVITY node-partition=
2017-11-12 12:41:58,389 DEBUG org.apache.hadoop.yarn.server.resourcemanager.scheduler.capacity.CapacityScheduler: nodeUpdate: hadoop-worker03:34047 clusterResources: <memory:24576, vCores:24>
2017-11-12 12:41:58,389 DEBUG org.apache.hadoop.yarn.server.resourcemanager.scheduler.capacity.CapacityScheduler: Node being looked for scheduling hadoop-worker03:34047 availableResource: <memory:8192, vCores:8>
2017-11-12 12:41:58,389 DEBUG org.apache.hadoop.yarn.server.resourcemanager.scheduler.capacity.CapacityScheduler: Trying to schedule on node: hadoop-worker03, available: <memory:8192, vCores:8>
2017-11-12 12:41:58,389 DEBUG org.apache.hadoop.yarn.server.resourcemanager.scheduler.capacity.ParentQueue: Skip this queue=root, because it doesn't need more resource, schedulingMode=RESPECT_PARTITION_EXCLUSIVITY node-partition=
2017-11-12 12:41:58,683 DEBUG org.apache.hadoop.yarn.server.resourcemanager.scheduler.capacity.CapacityScheduler: nodeUpdate: hadoop-worker02:35444 clusterResources: <memory:24576, vCores:24>
2017-11-12 12:41:58,683 DEBUG org.apache.hadoop.yarn.server.resourcemanager.scheduler.capacity.CapacityScheduler: Node being looked for scheduling hadoop-worker02:35444 availableResource: <memory:8192, vCores:8>
2017-11-12 12:41:58,683 DEBUG org.apache.hadoop.yarn.server.resourcemanager.scheduler.capacity.CapacityScheduler: Trying to schedule on node: hadoop-worker02, available: <memory:8192, vCores:8>
2017-11-12 12:41:58,683 DEBUG org.apache.hadoop.yarn.server.resourcemanager.scheduler.capacity.ParentQueue: Skip this queue=root, because it doesn't need more resource, schedulingMode=RESPECT_PARTITION_EXCLUSIVITY node-partition=
2017-11-12 12:41:58,887 DEBUG org.apache.hadoop.yarn.server.resourcemanager.scheduler.capacity.CapacityScheduler: nodeUpdate: hadoop-worker01:41792 clusterResources: <memory:24576, vCores:24>
2017-11-12 12:41:58,887 DEBUG org.apache.hadoop.yarn.server.resourcemanager.scheduler.capacity.CapacityScheduler: Node being looked for scheduling hadoop-worker01:41792 availableResource: <memory:8192, vCores:8>
2017-11-12 12:41:58,887 DEBUG org.apache.hadoop.yarn.server.resourcemanager.scheduler.capacity.CapacityScheduler: Trying to schedule on node: hadoop-worker01, available: <memory:8192, vCores:8>
2017-11-12 12:41:58,887 DEBUG org.apache.hadoop.yarn.server.resourcemanager.scheduler.capacity.ParentQueue: Skip this queue=root, because it doesn't need more resource, schedulingMode=RESPECT_PARTITION_EXCLUSIVITY node-partition=
2017-11-12 12:41:59,390 DEBUG org.apache.hadoop.yarn.server.resourcemanager.scheduler.capacity.CapacityScheduler: nodeUpdate: hadoop-worker03:34047 clusterResources: <memory:24576, vCores:24>
2017-11-12 12:41:59,390 DEBUG org.apache.hadoop.yarn.server.resourcemanager.scheduler.capacity.CapacityScheduler: Node being looked for scheduling hadoop-worker03:34047 availableResource: <memory:8192, vCores:8>
2017-11-12 12:41:59,390 DEBUG org.apache.hadoop.yarn.server.resourcemanager.scheduler.capacity.CapacityScheduler: Trying to schedule on node: hadoop-worker03, available: <memory:8192, vCores:8>
2017-11-12 12:41:59,390 DEBUG org.apache.hadoop.yarn.server.resourcemanager.scheduler.capacity.ParentQueue: Skip this queue=root, because it doesn't need more resource, schedulingMode=RESPECT_PARTITION_EXCLUSIVITY node-partition=
2017-11-12 12:41:59,685 DEBUG org.apache.hadoop.yarn.server.resourcemanager.scheduler.capacity.CapacityScheduler: nodeUpdate: hadoop-worker02:35444 clusterResources: <memory:24576, vCores:24>
2017-11-12 12:41:59,685 DEBUG org.apache.hadoop.yarn.server.resourcemanager.scheduler.capacity.CapacityScheduler: Node being looked for scheduling hadoop-worker02:35444 availableResource: <memory:8192, vCores:8>
2017-11-12 12:41:59,685 DEBUG org.apache.hadoop.yarn.server.resourcemanager.scheduler.capacity.CapacityScheduler: Trying to schedule on node: hadoop-worker02, available: <memory:8192, vCores:8>
2017-11-12 12:41:59,685 DEBUG org.apache.hadoop.yarn.server.resourcemanager.scheduler.capacity.ParentQueue: Skip this queue=root, because it doesn't need more resource, schedulingMode=RESPECT_PARTITION_EXCLUSIVITY node-partition=
2017-11-12 12:41:59,889 DEBUG org.apache.hadoop.yarn.server.resourcemanager.scheduler.capacity.CapacityScheduler: nodeUpdate: hadoop-worker01:41792 clusterResources: <memory:24576, vCores:24>
2017-11-12 12:41:59,889 DEBUG org.apache.hadoop.yarn.server.resourcemanager.scheduler.capacity.CapacityScheduler: Node being looked for scheduling hadoop-worker01:41792 availableResource: <memory:8192, vCores:8>
2017-11-12 12:41:59,889 DEBUG org.apache.hadoop.yarn.server.resourcemanager.scheduler.capacity.CapacityScheduler: Trying to schedule on node: hadoop-worker01, available: <memory:8192, vCores:8>
2017-11-12 12:41:59,889 DEBUG org.apache.hadoop.yarn.server.resourcemanager.scheduler.capacity.ParentQueue: Skip this queue=root, because it doesn't need more resource, schedulingMode=RESPECT_PARTITION_EXCLUSIVITY node-partition=
2017-11-12 12:42:00,392 DEBUG org.apache.hadoop.yarn.server.resourcemanager.scheduler.capacity.CapacityScheduler: nodeUpdate: hadoop-worker03:34047 clusterResources: <memory:24576, vCores:24>
2017-11-12 12:42:00,392 DEBUG org.apache.hadoop.yarn.server.resourcemanager.scheduler.capacity.CapacityScheduler: Node being looked for scheduling hadoop-worker03:34047 availableResource: <memory:8192, vCores:8>
2017-11-12 12:42:00,392 DEBUG org.apache.hadoop.yarn.server.resourcemanager.scheduler.capacity.CapacityScheduler: Trying to schedule on node: hadoop-worker03, available: <memory:8192, vCores:8>
2017-11-12 12:42:00,392 DEBUG org.apache.hadoop.yarn.server.resourcemanager.scheduler.capacity.ParentQueue: Skip this queue=root, because it doesn't need more resource, schedulingMode=RESPECT_PARTITION_EXCLUSIVITY node-partition=
2017-11-12 12:42:00,686 DEBUG org.apache.hadoop.yarn.server.resourcemanager.scheduler.capacity.CapacityScheduler: nodeUpdate: hadoop-worker02:35444 clusterResources: <memory:24576, vCores:24>
2017-11-12 12:42:00,686 DEBUG org.apache.hadoop.yarn.server.resourcemanager.scheduler.capacity.CapacityScheduler: Node being looked for scheduling hadoop-worker02:35444 availableResource: <memory:8192, vCores:8>
2017-11-12 12:42:00,686 DEBUG org.apache.hadoop.yarn.server.resourcemanager.scheduler.capacity.CapacityScheduler: Trying to schedule on node: hadoop-worker02, available: <memory:8192, vCores:8>
2017-11-12 12:42:00,686 DEBUG org.apache.hadoop.yarn.server.resourcemanager.scheduler.capacity.ParentQueue: Skip this queue=root, because it doesn't need more resource, schedulingMode=RESPECT_PARTITION_EXCLUSIVITY node-partition=
2017-11-12 12:42:00,891 DEBUG org.apache.hadoop.yarn.server.resourcemanager.scheduler.capacity.CapacityScheduler: nodeUpdate: hadoop-worker01:41792 clusterResources: <memory:24576, vCores:24>
2017-11-12 12:42:00,891 DEBUG org.apache.hadoop.yarn.server.resourcemanager.scheduler.capacity.CapacityScheduler: Node being looked for scheduling hadoop-worker01:41792 availableResource: <memory:8192, vCores:8>
2017-11-12 12:42:00,891 DEBUG org.apache.hadoop.yarn.server.resourcemanager.scheduler.capacity.CapacityScheduler: Trying to schedule on node: hadoop-worker01, available: <memory:8192, vCores:8>
2017-11-12 12:42:00,891 DEBUG org.apache.hadoop.yarn.server.resourcemanager.scheduler.capacity.ParentQueue: Skip this queue=root, because it doesn't need more resource, schedulingMode=RESPECT_PARTITION_EXCLUSIVITY node-partition=
2017-11-12 12:42:01,394 DEBUG org.apache.hadoop.yarn.server.resourcemanager.scheduler.capacity.CapacityScheduler: nodeUpdate: hadoop-worker03:34047 clusterResources: <memory:24576, vCores:24>
2017-11-12 12:42:01,394 DEBUG org.apache.hadoop.yarn.server.resourcemanager.scheduler.capacity.CapacityScheduler: Node being looked for scheduling hadoop-worker03:34047 availableResource: <memory:8192, vCores:8>
2017-11-12 12:42:01,394 DEBUG org.apache.hadoop.yarn.server.resourcemanager.scheduler.capacity.CapacityScheduler: Trying to schedule on node: hadoop-worker03, available: <memory:8192, vCores:8>
2017-11-12 12:42:01,394 DEBUG org.apache.hadoop.yarn.server.resourcemanager.scheduler.capacity.ParentQueue: Skip this queue=root, because it doesn't need more resource, schedulingMode=RESPECT_PARTITION_EXCLUSIVITY node-partition=
2017-11-12 12:42:01,690 DEBUG org.apache.hadoop.yarn.server.resourcemanager.scheduler.capacity.CapacityScheduler: nodeUpdate: hadoop-worker02:35444 clusterResources: <memory:24576, vCores:24>
2017-11-12 12:42:01,690 DEBUG org.apache.hadoop.yarn.server.resourcemanager.scheduler.capacity.CapacityScheduler: Node being looked for scheduling hadoop-worker02:35444 availableResource: <memory:8192, vCores:8>
2017-11-12 12:42:01,690 DEBUG org.apache.hadoop.yarn.server.resourcemanager.scheduler.capacity.CapacityScheduler: Trying to schedule on node: hadoop-worker02, available: <memory:8192, vCores:8>
2017-11-12 12:42:01,690 DEBUG org.apache.hadoop.yarn.server.resourcemanager.scheduler.capacity.ParentQueue: Skip this queue=root, because it doesn't need more resource, schedulingMode=RESPECT_PARTITION_EXCLUSIVITY node-partition=
2017-11-12 12:42:01,894 DEBUG org.apache.hadoop.yarn.server.resourcemanager.scheduler.capacity.CapacityScheduler: nodeUpdate: hadoop-worker01:41792 clusterResources: <memory:24576, vCores:24>
2017-11-12 12:42:01,894 DEBUG org.apache.hadoop.yarn.server.resourcemanager.scheduler.capacity.CapacityScheduler: Node being looked for scheduling hadoop-worker01:41792 availableResource: <memory:8192, vCores:8>
2017-11-12 12:42:01,894 DEBUG org.apache.hadoop.yarn.server.resourcemanager.scheduler.capacity.CapacityScheduler: Trying to schedule on node: hadoop-worker01, available: <memory:8192, vCores:8>
2017-11-12 12:42:01,894 DEBUG org.apache.hadoop.yarn.server.resourcemanager.scheduler.capacity.ParentQueue: Skip this queue=root, because it doesn't need more resource, schedulingMode=RESPECT_PARTITION_EXCLUSIVITY node-partition=
2017-11-12 12:42:02,403 DEBUG org.apache.hadoop.yarn.server.resourcemanager.scheduler.capacity.CapacityScheduler: nodeUpdate: hadoop-worker03:34047 clusterResources: <memory:24576, vCores:24>
2017-11-12 12:42:02,403 DEBUG org.apache.hadoop.yarn.server.resourcemanager.scheduler.capacity.CapacityScheduler: Node being looked for scheduling hadoop-worker03:34047 availableResource: <memory:8192, vCores:8>
2017-11-12 12:42:02,403 DEBUG org.apache.hadoop.yarn.server.resourcemanager.scheduler.capacity.CapacityScheduler: Trying to schedule on node: hadoop-worker03, available: <memory:8192, vCores:8>
2017-11-12 12:42:02,403 DEBUG org.apache.hadoop.yarn.server.resourcemanager.scheduler.capacity.ParentQueue: Skip this queue=root, because it doesn't need more resource, schedulingMode=RESPECT_PARTITION_EXCLUSIVITY node-partition=
2017-11-12 12:42:02,693 DEBUG org.apache.hadoop.yarn.server.resourcemanager.scheduler.capacity.CapacityScheduler: nodeUpdate: hadoop-worker02:35444 clusterResources: <memory:24576, vCores:24>
2017-11-12 12:42:02,693 DEBUG org.apache.hadoop.yarn.server.resourcemanager.scheduler.capacity.CapacityScheduler: Node being looked for scheduling hadoop-worker02:35444 availableResource: <memory:8192, vCores:8>
2017-11-12 12:42:02,693 DEBUG org.apache.hadoop.yarn.server.resourcemanager.scheduler.capacity.CapacityScheduler: Trying to schedule on node: hadoop-worker02, available: <memory:8192, vCores:8>
2017-11-12 12:42:02,693 DEBUG org.apache.hadoop.yarn.server.resourcemanager.scheduler.capacity.ParentQueue: Skip this queue=root, because it doesn't need more resource, schedulingMode=RESPECT_PARTITION_EXCLUSIVITY node-partition=
2017-11-12 12:42:02,896 DEBUG org.apache.hadoop.yarn.server.resourcemanager.scheduler.capacity.CapacityScheduler: nodeUpdate: hadoop-worker01:41792 clusterResources: <memory:24576, vCores:24>
2017-11-12 12:42:02,896 DEBUG org.apache.hadoop.yarn.server.resourcemanager.scheduler.capacity.CapacityScheduler: Node being looked for scheduling hadoop-worker01:41792 availableResource: <memory:8192, vCores:8>
2017-11-12 12:42:02,896 DEBUG org.apache.hadoop.yarn.server.resourcemanager.scheduler.capacity.CapacityScheduler: Trying to schedule on node: hadoop-worker01, available: <memory:8192, vCores:8>
2017-11-12 12:42:02,896 DEBUG org.apache.hadoop.yarn.server.resourcemanager.scheduler.capacity.ParentQueue: Skip this queue=root, because it doesn't need more resource, schedulingMode=RESPECT_PARTITION_EXCLUSIVITY node-partition=
2017-11-12 12:42:03,404 DEBUG org.apache.hadoop.yarn.server.resourcemanager.scheduler.capacity.CapacityScheduler: nodeUpdate: hadoop-worker03:34047 clusterResources: <memory:24576, vCores:24>
2017-11-12 12:42:03,404 DEBUG org.apache.hadoop.yarn.server.resourcemanager.scheduler.capacity.CapacityScheduler: Node being looked for scheduling hadoop-worker03:34047 availableResource: <memory:8192, vCores:8>
2017-11-12 12:42:03,404 DEBUG org.apache.hadoop.yarn.server.resourcemanager.scheduler.capacity.CapacityScheduler: Trying to schedule on node: hadoop-worker03, available: <memory:8192, vCores:8>
2017-11-12 12:42:03,404 DEBUG org.apache.hadoop.yarn.server.resourcemanager.scheduler.capacity.ParentQueue: Skip this queue=root, because it doesn't need more resource, schedulingMode=RESPECT_PARTITION_EXCLUSIVITY node-partition=
2017-11-12 12:42:03,696 DEBUG org.apache.hadoop.yarn.server.resourcemanager.scheduler.capacity.CapacityScheduler: nodeUpdate: hadoop-worker02:35444 clusterResources: <memory:24576, vCores:24>
2017-11-12 12:42:03,696 DEBUG org.apache.hadoop.yarn.server.resourcemanager.scheduler.capacity.CapacityScheduler: Node being looked for scheduling hadoop-worker02:35444 availableResource: <memory:8192, vCores:8>
2017-11-12 12:42:03,696 DEBUG org.apache.hadoop.yarn.server.resourcemanager.scheduler.capacity.CapacityScheduler: Trying to schedule on node: hadoop-worker02, available: <memory:8192, vCores:8>
2017-11-12 12:42:03,696 DEBUG org.apache.hadoop.yarn.server.resourcemanager.scheduler.capacity.ParentQueue: Skip this queue=root, because it doesn't need more resource, schedulingMode=RESPECT_PARTITION_EXCLUSIVITY node-partition=
2017-11-12 12:42:03,897 DEBUG org.apache.hadoop.yarn.server.resourcemanager.scheduler.capacity.CapacityScheduler: nodeUpdate: hadoop-worker01:41792 clusterResources: <memory:24576, vCores:24>
2017-11-12 12:42:03,897 DEBUG org.apache.hadoop.yarn.server.resourcemanager.scheduler.capacity.CapacityScheduler: Node being looked for scheduling hadoop-worker01:41792 availableResource: <memory:8192, vCores:8>
2017-11-12 12:42:03,897 DEBUG org.apache.hadoop.yarn.server.resourcemanager.scheduler.capacity.CapacityScheduler: Trying to schedule on node: hadoop-worker01, available: <memory:8192, vCores:8>
2017-11-12 12:42:03,897 DEBUG org.apache.hadoop.yarn.server.resourcemanager.scheduler.capacity.ParentQueue: Skip this queue=root, because it doesn't need more resource, schedulingMode=RESPECT_PARTITION_EXCLUSIVITY node-partition=
2017-11-12 12:42:04,406 DEBUG org.apache.hadoop.yarn.server.resourcemanager.scheduler.capacity.CapacityScheduler: nodeUpdate: hadoop-worker03:34047 clusterResources: <memory:24576, vCores:24>
2017-11-12 12:42:04,406 DEBUG org.apache.hadoop.yarn.server.resourcemanager.scheduler.capacity.CapacityScheduler: Node being looked for scheduling hadoop-worker03:34047 availableResource: <memory:8192, vCores:8>
2017-11-12 12:42:04,406 DEBUG org.apache.hadoop.yarn.server.resourcemanager.scheduler.capacity.CapacityScheduler: Trying to schedule on node: hadoop-worker03, available: <memory:8192, vCores:8>
2017-11-12 12:42:04,406 DEBUG org.apache.hadoop.yarn.server.resourcemanager.scheduler.capacity.ParentQueue: Skip this queue=root, because it doesn't need more resource, schedulingMode=RESPECT_PARTITION_EXCLUSIVITY node-partition=
2017-11-12 12:42:04,696 DEBUG org.apache.hadoop.yarn.server.resourcemanager.scheduler.capacity.CapacityScheduler: nodeUpdate: hadoop-worker02:35444 clusterResources: <memory:24576, vCores:24>
2017-11-12 12:42:04,696 DEBUG org.apache.hadoop.yarn.server.resourcemanager.scheduler.capacity.CapacityScheduler: Node being looked for scheduling hadoop-worker02:35444 availableResource: <memory:8192, vCores:8>
2017-11-12 12:42:04,696 DEBUG org.apache.hadoop.yarn.server.resourcemanager.scheduler.capacity.CapacityScheduler: Trying to schedule on node: hadoop-worker02, available: <memory:8192, vCores:8>
2017-11-12 12:42:04,696 DEBUG org.apache.hadoop.yarn.server.resourcemanager.scheduler.capacity.ParentQueue: Skip this queue=root, because it doesn't need more resource, schedulingMode=RESPECT_PARTITION_EXCLUSIVITY node-partition=
2017-11-12 12:42:04,899 DEBUG org.apache.hadoop.yarn.server.resourcemanager.scheduler.capacity.CapacityScheduler: nodeUpdate: hadoop-worker01:41792 clusterResources: <memory:24576, vCores:24>
2017-11-12 12:42:04,899 DEBUG org.apache.hadoop.yarn.server.resourcemanager.scheduler.capacity.CapacityScheduler: Node being looked for scheduling hadoop-worker01:41792 availableResource: <memory:8192, vCores:8>
2017-11-12 12:42:04,899 DEBUG org.apache.hadoop.yarn.server.resourcemanager.scheduler.capacity.CapacityScheduler: Trying to schedule on node: hadoop-worker01, available: <memory:8192, vCores:8>
2017-11-12 12:42:04,899 DEBUG org.apache.hadoop.yarn.server.resourcemanager.scheduler.capacity.ParentQueue: Skip this queue=root, because it doesn't need more resource, schedulingMode=RESPECT_PARTITION_EXCLUSIVITY node-partition=
2017-11-12 12:42:05,408 DEBUG org.apache.hadoop.yarn.server.resourcemanager.scheduler.capacity.CapacityScheduler: nodeUpdate: hadoop-worker03:34047 clusterResources: <memory:24576, vCores:24>
2017-11-12 12:42:05,408 DEBUG org.apache.hadoop.yarn.server.resourcemanager.scheduler.capacity.CapacityScheduler: Node being looked for scheduling hadoop-worker03:34047 availableResource: <memory:8192, vCores:8>
2017-11-12 12:42:05,409 DEBUG org.apache.hadoop.yarn.server.resourcemanager.scheduler.capacity.CapacityScheduler: Trying to schedule on node: hadoop-worker03, available: <memory:8192, vCores:8>
2017-11-12 12:42:05,409 DEBUG org.apache.hadoop.yarn.server.resourcemanager.scheduler.capacity.ParentQueue: Skip this queue=root, because it doesn't need more resource, schedulingMode=RESPECT_PARTITION_EXCLUSIVITY node-partition=
2017-11-12 12:42:05,697 DEBUG org.apache.hadoop.yarn.server.resourcemanager.scheduler.capacity.CapacityScheduler: nodeUpdate: hadoop-worker02:35444 clusterResources: <memory:24576, vCores:24>
2017-11-12 12:42:05,697 DEBUG org.apache.hadoop.yarn.server.resourcemanager.scheduler.capacity.CapacityScheduler: Node being looked for scheduling hadoop-worker02:35444 availableResource: <memory:8192, vCores:8>
2017-11-12 12:42:05,697 DEBUG org.apache.hadoop.yarn.server.resourcemanager.scheduler.capacity.CapacityScheduler: Trying to schedule on node: hadoop-worker02, available: <memory:8192, vCores:8>
2017-11-12 12:42:05,697 DEBUG org.apache.hadoop.yarn.server.resourcemanager.scheduler.capacity.ParentQueue: Skip this queue=root, because it doesn't need more resource, schedulingMode=RESPECT_PARTITION_EXCLUSIVITY node-partition=
2017-11-12 12:42:05,900 DEBUG org.apache.hadoop.yarn.server.resourcemanager.scheduler.capacity.CapacityScheduler: nodeUpdate: hadoop-worker01:41792 clusterResources: <memory:24576, vCores:24>
2017-11-12 12:42:05,900 DEBUG org.apache.hadoop.yarn.server.resourcemanager.scheduler.capacity.CapacityScheduler: Node being looked for scheduling hadoop-worker01:41792 availableResource: <memory:8192, vCores:8>
2017-11-12 12:42:05,900 DEBUG org.apache.hadoop.yarn.server.resourcemanager.scheduler.capacity.CapacityScheduler: Trying to schedule on node: hadoop-worker01, available: <memory:8192, vCores:8>
2017-11-12 12:42:05,900 DEBUG org.apache.hadoop.yarn.server.resourcemanager.scheduler.capacity.ParentQueue: Skip this queue=root, because it doesn't need more resource, schedulingMode=RESPECT_PARTITION_EXCLUSIVITY node-partition=
2017-11-12 12:42:06,410 DEBUG org.apache.hadoop.yarn.server.resourcemanager.scheduler.capacity.CapacityScheduler: nodeUpdate: hadoop-worker03:34047 clusterResources: <memory:24576, vCores:24>
2017-11-12 12:42:06,410 DEBUG org.apache.hadoop.yarn.server.resourcemanager.scheduler.capacity.CapacityScheduler: Node being looked for scheduling hadoop-worker03:34047 availableResource: <memory:8192, vCores:8>
2017-11-12 12:42:06,410 DEBUG org.apache.hadoop.yarn.server.resourcemanager.scheduler.capacity.CapacityScheduler: Trying to schedule on node: hadoop-worker03, available: <memory:8192, vCores:8>
2017-11-12 12:42:06,410 DEBUG org.apache.hadoop.yarn.server.resourcemanager.scheduler.capacity.ParentQueue: Skip this queue=root, because it doesn't need more resource, schedulingMode=RESPECT_PARTITION_EXCLUSIVITY node-partition=
2017-11-12 12:42:06,699 DEBUG org.apache.hadoop.yarn.server.resourcemanager.scheduler.capacity.CapacityScheduler: nodeUpdate: hadoop-worker02:35444 clusterResources: <memory:24576, vCores:24>
2017-11-12 12:42:06,699 DEBUG org.apache.hadoop.yarn.server.resourcemanager.scheduler.capacity.CapacityScheduler: Node being looked for scheduling hadoop-worker02:35444 availableResource: <memory:8192, vCores:8>
2017-11-12 12:42:06,699 DEBUG org.apache.hadoop.yarn.server.resourcemanager.scheduler.capacity.CapacityScheduler: Trying to schedule on node: hadoop-worker02, available: <memory:8192, vCores:8>
2017-11-12 12:42:06,699 DEBUG org.apache.hadoop.yarn.server.resourcemanager.scheduler.capacity.ParentQueue: Skip this queue=root, because it doesn't need more resource, schedulingMode=RESPECT_PARTITION_EXCLUSIVITY node-partition=
2017-11-12 12:42:06,902 DEBUG org.apache.hadoop.yarn.server.resourcemanager.scheduler.capacity.CapacityScheduler: nodeUpdate: hadoop-worker01:41792 clusterResources: <memory:24576, vCores:24>
2017-11-12 12:42:06,902 DEBUG org.apache.hadoop.yarn.server.resourcemanager.scheduler.capacity.CapacityScheduler: Node being looked for scheduling hadoop-worker01:41792 availableResource: <memory:8192, vCores:8>
2017-11-12 12:42:06,902 DEBUG org.apache.hadoop.yarn.server.resourcemanager.scheduler.capacity.CapacityScheduler: Trying to schedule on node: hadoop-worker01, available: <memory:8192, vCores:8>
2017-11-12 12:42:06,902 DEBUG org.apache.hadoop.yarn.server.resourcemanager.scheduler.capacity.ParentQueue: Skip this queue=root, because it doesn't need more resource, schedulingMode=RESPECT_PARTITION_EXCLUSIVITY node-partition=
2017-11-12 12:42:07,412 DEBUG org.apache.hadoop.yarn.server.resourcemanager.scheduler.capacity.CapacityScheduler: nodeUpdate: hadoop-worker03:34047 clusterResources: <memory:24576, vCores:24>
2017-11-12 12:42:07,412 DEBUG org.apache.hadoop.yarn.server.resourcemanager.scheduler.capacity.CapacityScheduler: Node being looked for scheduling hadoop-worker03:34047 availableResource: <memory:8192, vCores:8>
2017-11-12 12:42:07,412 DEBUG org.apache.hadoop.yarn.server.resourcemanager.scheduler.capacity.CapacityScheduler: Trying to schedule on node: hadoop-worker03, available: <memory:8192, vCores:8>
2017-11-12 12:42:07,412 DEBUG org.apache.hadoop.yarn.server.resourcemanager.scheduler.capacity.ParentQueue: Skip this queue=root, because it doesn't need more resource, schedulingMode=RESPECT_PARTITION_EXCLUSIVITY node-partition=
2017-11-12 12:42:07,708 DEBUG org.apache.hadoop.yarn.server.resourcemanager.scheduler.capacity.CapacityScheduler: nodeUpdate: hadoop-worker02:35444 clusterResources: <memory:24576, vCores:24>
2017-11-12 12:42:07,708 DEBUG org.apache.hadoop.yarn.server.resourcemanager.scheduler.capacity.CapacityScheduler: Node being looked for scheduling hadoop-worker02:35444 availableResource: <memory:8192, vCores:8>
2017-11-12 12:42:07,708 DEBUG org.apache.hadoop.yarn.server.resourcemanager.scheduler.capacity.CapacityScheduler: Trying to schedule on node: hadoop-worker02, available: <memory:8192, vCores:8>
2017-11-12 12:42:07,708 DEBUG org.apache.hadoop.yarn.server.resourcemanager.scheduler.capacity.ParentQueue: Skip this queue=root, because it doesn't need more resource, schedulingMode=RESPECT_PARTITION_EXCLUSIVITY node-partition=
2017-11-12 12:42:07,905 DEBUG org.apache.hadoop.yarn.server.resourcemanager.scheduler.capacity.CapacityScheduler: nodeUpdate: hadoop-worker01:41792 clusterResources: <memory:24576, vCores:24>
2017-11-12 12:42:07,905 DEBUG org.apache.hadoop.yarn.server.resourcemanager.scheduler.capacity.CapacityScheduler: Node being looked for scheduling hadoop-worker01:41792 availableResource: <memory:8192, vCores:8>
2017-11-12 12:42:07,905 DEBUG org.apache.hadoop.yarn.server.resourcemanager.scheduler.capacity.CapacityScheduler: Trying to schedule on node: hadoop-worker01, available: <memory:8192, vCores:8>
2017-11-12 12:42:07,905 DEBUG org.apache.hadoop.yarn.server.resourcemanager.scheduler.capacity.ParentQueue: Skip this queue=root, because it doesn't need more resource, schedulingMode=RESPECT_PARTITION_EXCLUSIVITY node-partition=
2017-11-12 12:42:08,413 DEBUG org.apache.hadoop.yarn.server.resourcemanager.scheduler.capacity.CapacityScheduler: nodeUpdate: hadoop-worker03:34047 clusterResources: <memory:24576, vCores:24>
2017-11-12 12:42:08,413 DEBUG org.apache.hadoop.yarn.server.resourcemanager.scheduler.capacity.CapacityScheduler: Node being looked for scheduling hadoop-worker03:34047 availableResource: <memory:8192, vCores:8>
2017-11-12 12:42:08,413 DEBUG org.apache.hadoop.yarn.server.resourcemanager.scheduler.capacity.CapacityScheduler: Trying to schedule on node: hadoop-worker03, available: <memory:8192, vCores:8>
2017-11-12 12:42:08,413 DEBUG org.apache.hadoop.yarn.server.resourcemanager.scheduler.capacity.ParentQueue: Skip this queue=root, because it doesn't need more resource, schedulingMode=RESPECT_PARTITION_EXCLUSIVITY node-partition=
2017-11-12 12:42:08,709 DEBUG org.apache.hadoop.yarn.server.resourcemanager.scheduler.capacity.CapacityScheduler: nodeUpdate: hadoop-worker02:35444 clusterResources: <memory:24576, vCores:24>
2017-11-12 12:42:08,709 DEBUG org.apache.hadoop.yarn.server.resourcemanager.scheduler.capacity.CapacityScheduler: Node being looked for scheduling hadoop-worker02:35444 availableResource: <memory:8192, vCores:8>
2017-11-12 12:42:08,709 DEBUG org.apache.hadoop.yarn.server.resourcemanager.scheduler.capacity.CapacityScheduler: Trying to schedule on node: hadoop-worker02, available: <memory:8192, vCores:8>
2017-11-12 12:42:08,709 DEBUG org.apache.hadoop.yarn.server.resourcemanager.scheduler.capacity.ParentQueue: Skip this queue=root, because it doesn't need more resource, schedulingMode=RESPECT_PARTITION_EXCLUSIVITY node-partition=
2017-11-12 12:42:08,907 DEBUG org.apache.hadoop.yarn.server.resourcemanager.scheduler.capacity.CapacityScheduler: nodeUpdate: hadoop-worker01:41792 clusterResources: <memory:24576, vCores:24>
2017-11-12 12:42:08,907 DEBUG org.apache.hadoop.yarn.server.resourcemanager.scheduler.capacity.CapacityScheduler: Node being looked for scheduling hadoop-worker01:41792 availableResource: <memory:8192, vCores:8>
2017-11-12 12:42:08,907 DEBUG org.apache.hadoop.yarn.server.resourcemanager.scheduler.capacity.CapacityScheduler: Trying to schedule on node: hadoop-worker01, available: <memory:8192, vCores:8>
2017-11-12 12:42:08,907 DEBUG org.apache.hadoop.yarn.server.resourcemanager.scheduler.capacity.ParentQueue: Skip this queue=root, because it doesn't need more resource, schedulingMode=RESPECT_PARTITION_EXCLUSIVITY node-partition=
2017-11-12 12:42:09,414 DEBUG org.apache.hadoop.yarn.server.resourcemanager.scheduler.capacity.CapacityScheduler: nodeUpdate: hadoop-worker03:34047 clusterResources: <memory:24576, vCores:24>
2017-11-12 12:42:09,414 DEBUG org.apache.hadoop.yarn.server.resourcemanager.scheduler.capacity.CapacityScheduler: Node being looked for scheduling hadoop-worker03:34047 availableResource: <memory:8192, vCores:8>
2017-11-12 12:42:09,414 DEBUG org.apache.hadoop.yarn.server.resourcemanager.scheduler.capacity.CapacityScheduler: Trying to schedule on node: hadoop-worker03, available: <memory:8192, vCores:8>
2017-11-12 12:42:09,414 DEBUG org.apache.hadoop.yarn.server.resourcemanager.scheduler.capacity.ParentQueue: Skip this queue=root, because it doesn't need more resource, schedulingMode=RESPECT_PARTITION_EXCLUSIVITY node-partition=
2017-11-12 12:42:09,711 DEBUG org.apache.hadoop.yarn.server.resourcemanager.scheduler.capacity.CapacityScheduler: nodeUpdate: hadoop-worker02:35444 clusterResources: <memory:24576, vCores:24>
2017-11-12 12:42:09,711 DEBUG org.apache.hadoop.yarn.server.resourcemanager.scheduler.capacity.CapacityScheduler: Node being looked for scheduling hadoop-worker02:35444 availableResource: <memory:8192, vCores:8>
2017-11-12 12:42:09,711 DEBUG org.apache.hadoop.yarn.server.resourcemanager.scheduler.capacity.CapacityScheduler: Trying to schedule on node: hadoop-worker02, available: <memory:8192, vCores:8>
2017-11-12 12:42:09,711 DEBUG org.apache.hadoop.yarn.server.resourcemanager.scheduler.capacity.ParentQueue: Skip this queue=root, because it doesn't need more resource, schedulingMode=RESPECT_PARTITION_EXCLUSIVITY node-partition=
2017-11-12 12:42:09,908 DEBUG org.apache.hadoop.yarn.server.resourcemanager.scheduler.capacity.CapacityScheduler: nodeUpdate: hadoop-worker01:41792 clusterResources: <memory:24576, vCores:24>
2017-11-12 12:42:09,908 DEBUG org.apache.hadoop.yarn.server.resourcemanager.scheduler.capacity.CapacityScheduler: Node being looked for scheduling hadoop-worker01:41792 availableResource: <memory:8192, vCores:8>
2017-11-12 12:42:09,908 DEBUG org.apache.hadoop.yarn.server.resourcemanager.scheduler.capacity.CapacityScheduler: Trying to schedule on node: hadoop-worker01, available: <memory:8192, vCores:8>
2017-11-12 12:42:09,908 DEBUG org.apache.hadoop.yarn.server.resourcemanager.scheduler.capacity.ParentQueue: Skip this queue=root, because it doesn't need more resource, schedulingMode=RESPECT_PARTITION_EXCLUSIVITY node-partition=
2017-11-12 12:42:10,404 DEBUG org.apache.hadoop.yarn.server.resourcemanager.scheduler.capacity.CapacityScheduler: nodeUpdate: hadoop-worker03:34047 clusterResources: <memory:24576, vCores:24>
2017-11-12 12:42:10,404 DEBUG org.apache.hadoop.yarn.server.resourcemanager.scheduler.capacity.CapacityScheduler: Node being looked for scheduling hadoop-worker03:34047 availableResource: <memory:8192, vCores:8>
2017-11-12 12:42:10,404 DEBUG org.apache.hadoop.yarn.server.resourcemanager.scheduler.capacity.CapacityScheduler: Trying to schedule on node: hadoop-worker03, available: <memory:8192, vCores:8>
2017-11-12 12:42:10,404 DEBUG org.apache.hadoop.yarn.server.resourcemanager.scheduler.capacity.ParentQueue: Skip this queue=root, because it doesn't need more resource, schedulingMode=RESPECT_PARTITION_EXCLUSIVITY node-partition=
2017-11-12 12:42:10,716 DEBUG org.apache.hadoop.yarn.server.resourcemanager.scheduler.capacity.CapacityScheduler: nodeUpdate: hadoop-worker02:35444 clusterResources: <memory:24576, vCores:24>
2017-11-12 12:42:10,716 DEBUG org.apache.hadoop.yarn.server.resourcemanager.scheduler.capacity.CapacityScheduler: Node being looked for scheduling hadoop-worker02:35444 availableResource: <memory:8192, vCores:8>
2017-11-12 12:42:10,716 DEBUG org.apache.hadoop.yarn.server.resourcemanager.scheduler.capacity.CapacityScheduler: Trying to schedule on node: hadoop-worker02, available: <memory:8192, vCores:8>
2017-11-12 12:42:10,716 DEBUG org.apache.hadoop.yarn.server.resourcemanager.scheduler.capacity.ParentQueue: Skip this queue=root, because it doesn't need more resource, schedulingMode=RESPECT_PARTITION_EXCLUSIVITY node-partition=
2017-11-12 12:42:10,910 DEBUG org.apache.hadoop.yarn.server.resourcemanager.scheduler.capacity.CapacityScheduler: nodeUpdate: hadoop-worker01:41792 clusterResources: <memory:24576, vCores:24>
2017-11-12 12:42:10,910 DEBUG org.apache.hadoop.yarn.server.resourcemanager.scheduler.capacity.CapacityScheduler: Node being looked for scheduling hadoop-worker01:41792 availableResource: <memory:8192, vCores:8>
2017-11-12 12:42:10,910 DEBUG org.apache.hadoop.yarn.server.resourcemanager.scheduler.capacity.CapacityScheduler: Trying to schedule on node: hadoop-worker01, available: <memory:8192, vCores:8>
2017-11-12 12:42:10,910 DEBUG org.apache.hadoop.yarn.server.resourcemanager.scheduler.capacity.ParentQueue: Skip this queue=root, because it doesn't need more resource, schedulingMode=RESPECT_PARTITION_EXCLUSIVITY node-partition=
2017-11-12 12:42:11,338 DEBUG org.apache.hadoop.yarn.server.resourcemanager.scheduler.capacity.CapacityScheduler: nodeUpdate: hadoop-worker03:34047 clusterResources: <memory:24576, vCores:24>
2017-11-12 12:42:11,338 DEBUG org.apache.hadoop.yarn.server.resourcemanager.scheduler.capacity.CapacityScheduler: Node being looked for scheduling hadoop-worker03:34047 availableResource: <memory:8192, vCores:8>
2017-11-12 12:42:11,338 DEBUG org.apache.hadoop.yarn.server.resourcemanager.scheduler.capacity.CapacityScheduler: Trying to schedule on node: hadoop-worker03, available: <memory:8192, vCores:8>
2017-11-12 12:42:11,338 DEBUG org.apache.hadoop.yarn.server.resourcemanager.scheduler.capacity.ParentQueue: Skip this queue=root, because it doesn't need more resource, schedulingMode=RESPECT_PARTITION_EXCLUSIVITY node-partition=
2017-11-12 12:42:11,719 DEBUG org.apache.hadoop.yarn.server.resourcemanager.scheduler.capacity.CapacityScheduler: nodeUpdate: hadoop-worker02:35444 clusterResources: <memory:24576, vCores:24>
2017-11-12 12:42:11,719 DEBUG org.apache.hadoop.yarn.server.resourcemanager.scheduler.capacity.CapacityScheduler: Node being looked for scheduling hadoop-worker02:35444 availableResource: <memory:8192, vCores:8>
2017-11-12 12:42:11,719 DEBUG org.apache.hadoop.yarn.server.resourcemanager.scheduler.capacity.CapacityScheduler: Trying to schedule on node: hadoop-worker02, available: <memory:8192, vCores:8>
2017-11-12 12:42:11,719 DEBUG org.apache.hadoop.yarn.server.resourcemanager.scheduler.capacity.ParentQueue: Skip this queue=root, because it doesn't need more resource, schedulingMode=RESPECT_PARTITION_EXCLUSIVITY node-partition=
2017-11-12 12:42:11,911 DEBUG org.apache.hadoop.yarn.server.resourcemanager.scheduler.capacity.CapacityScheduler: nodeUpdate: hadoop-worker01:41792 clusterResources: <memory:24576, vCores:24>
2017-11-12 12:42:11,912 DEBUG org.apache.hadoop.yarn.server.resourcemanager.scheduler.capacity.CapacityScheduler: Node being looked for scheduling hadoop-worker01:41792 availableResource: <memory:8192, vCores:8>
2017-11-12 12:42:11,912 DEBUG org.apache.hadoop.yarn.server.resourcemanager.scheduler.capacity.CapacityScheduler: Trying to schedule on node: hadoop-worker01, available: <memory:8192, vCores:8>
2017-11-12 12:42:11,912 DEBUG org.apache.hadoop.yarn.server.resourcemanager.scheduler.capacity.ParentQueue: Skip this queue=root, because it doesn't need more resource, schedulingMode=RESPECT_PARTITION_EXCLUSIVITY node-partition=
2017-11-12 12:42:12,339 DEBUG org.apache.hadoop.yarn.server.resourcemanager.scheduler.capacity.CapacityScheduler: nodeUpdate: hadoop-worker03:34047 clusterResources: <memory:24576, vCores:24>
2017-11-12 12:42:12,339 DEBUG org.apache.hadoop.yarn.server.resourcemanager.scheduler.capacity.CapacityScheduler: Node being looked for scheduling hadoop-worker03:34047 availableResource: <memory:8192, vCores:8>
2017-11-12 12:42:12,339 DEBUG org.apache.hadoop.yarn.server.resourcemanager.scheduler.capacity.CapacityScheduler: Trying to schedule on node: hadoop-worker03, available: <memory:8192, vCores:8>
2017-11-12 12:42:12,339 DEBUG org.apache.hadoop.yarn.server.resourcemanager.scheduler.capacity.ParentQueue: Skip this queue=root, because it doesn't need more resource, schedulingMode=RESPECT_PARTITION_EXCLUSIVITY node-partition=
2017-11-12 12:42:12,721 DEBUG org.apache.hadoop.yarn.server.resourcemanager.scheduler.capacity.CapacityScheduler: nodeUpdate: hadoop-worker02:35444 clusterResources: <memory:24576, vCores:24>
2017-11-12 12:42:12,721 DEBUG org.apache.hadoop.yarn.server.resourcemanager.scheduler.capacity.CapacityScheduler: Node being looked for scheduling hadoop-worker02:35444 availableResource: <memory:8192, vCores:8>
2017-11-12 12:42:12,721 DEBUG org.apache.hadoop.yarn.server.resourcemanager.scheduler.capacity.CapacityScheduler: Trying to schedule on node: hadoop-worker02, available: <memory:8192, vCores:8>
2017-11-12 12:42:12,721 DEBUG org.apache.hadoop.yarn.server.resourcemanager.scheduler.capacity.ParentQueue: Skip this queue=root, because it doesn't need more resource, schedulingMode=RESPECT_PARTITION_EXCLUSIVITY node-partition=
2017-11-12 12:42:12,915 DEBUG org.apache.hadoop.yarn.server.resourcemanager.scheduler.capacity.CapacityScheduler: nodeUpdate: hadoop-worker01:41792 clusterResources: <memory:24576, vCores:24>
2017-11-12 12:42:12,915 DEBUG org.apache.hadoop.yarn.server.resourcemanager.scheduler.capacity.CapacityScheduler: Node being looked for scheduling hadoop-worker01:41792 availableResource: <memory:8192, vCores:8>
2017-11-12 12:42:12,915 DEBUG org.apache.hadoop.yarn.server.resourcemanager.scheduler.capacity.CapacityScheduler: Trying to schedule on node: hadoop-worker01, available: <memory:8192, vCores:8>
2017-11-12 12:42:12,915 DEBUG org.apache.hadoop.yarn.server.resourcemanager.scheduler.capacity.ParentQueue: Skip this queue=root, because it doesn't need more resource, schedulingMode=RESPECT_PARTITION_EXCLUSIVITY node-partition=
2017-11-12 12:42:13,341 DEBUG org.apache.hadoop.yarn.server.resourcemanager.scheduler.capacity.CapacityScheduler: nodeUpdate: hadoop-worker03:34047 clusterResources: <memory:24576, vCores:24>
2017-11-12 12:42:13,341 DEBUG org.apache.hadoop.yarn.server.resourcemanager.scheduler.capacity.CapacityScheduler: Node being looked for scheduling hadoop-worker03:34047 availableResource: <memory:8192, vCores:8>
2017-11-12 12:42:13,341 DEBUG org.apache.hadoop.yarn.server.resourcemanager.scheduler.capacity.CapacityScheduler: Trying to schedule on node: hadoop-worker03, available: <memory:8192, vCores:8>
2017-11-12 12:42:13,341 DEBUG org.apache.hadoop.yarn.server.resourcemanager.scheduler.capacity.ParentQueue: Skip this queue=root, because it doesn't need more resource, schedulingMode=RESPECT_PARTITION_EXCLUSIVITY node-partition=
2017-11-12 12:42:13,722 DEBUG org.apache.hadoop.yarn.server.resourcemanager.scheduler.capacity.CapacityScheduler: nodeUpdate: hadoop-worker02:35444 clusterResources: <memory:24576, vCores:24>
2017-11-12 12:42:13,722 DEBUG org.apache.hadoop.yarn.server.resourcemanager.scheduler.capacity.CapacityScheduler: Node being looked for scheduling hadoop-worker02:35444 availableResource: <memory:8192, vCores:8>
2017-11-12 12:42:13,722 DEBUG org.apache.hadoop.yarn.server.resourcemanager.scheduler.capacity.CapacityScheduler: Trying to schedule on node: hadoop-worker02, available: <memory:8192, vCores:8>
2017-11-12 12:42:13,722 DEBUG org.apache.hadoop.yarn.server.resourcemanager.scheduler.capacity.ParentQueue: Skip this queue=root, because it doesn't need more resource, schedulingMode=RESPECT_PARTITION_EXCLUSIVITY node-partition=
2017-11-12 12:42:13,918 DEBUG org.apache.hadoop.yarn.server.resourcemanager.scheduler.capacity.CapacityScheduler: nodeUpdate: hadoop-worker01:41792 clusterResources: <memory:24576, vCores:24>
2017-11-12 12:42:13,918 DEBUG org.apache.hadoop.yarn.server.resourcemanager.scheduler.capacity.CapacityScheduler: Node being looked for scheduling hadoop-worker01:41792 availableResource: <memory:8192, vCores:8>
2017-11-12 12:42:13,918 DEBUG org.apache.hadoop.yarn.server.resourcemanager.scheduler.capacity.CapacityScheduler: Trying to schedule on node: hadoop-worker01, available: <memory:8192, vCores:8>
2017-11-12 12:42:13,918 DEBUG org.apache.hadoop.yarn.server.resourcemanager.scheduler.capacity.ParentQueue: Skip this queue=root, because it doesn't need more resource, schedulingMode=RESPECT_PARTITION_EXCLUSIVITY node-partition=
2017-11-12 12:42:14,342 DEBUG org.apache.hadoop.yarn.server.resourcemanager.scheduler.capacity.CapacityScheduler: nodeUpdate: hadoop-worker03:34047 clusterResources: <memory:24576, vCores:24>
2017-11-12 12:42:14,342 DEBUG org.apache.hadoop.yarn.server.resourcemanager.scheduler.capacity.CapacityScheduler: Node being looked for scheduling hadoop-worker03:34047 availableResource: <memory:8192, vCores:8>
2017-11-12 12:42:14,342 DEBUG org.apache.hadoop.yarn.server.resourcemanager.scheduler.capacity.CapacityScheduler: Trying to schedule on node: hadoop-worker03, available: <memory:8192, vCores:8>
2017-11-12 12:42:14,342 DEBUG org.apache.hadoop.yarn.server.resourcemanager.scheduler.capacity.ParentQueue: Skip this queue=root, because it doesn't need more resource, schedulingMode=RESPECT_PARTITION_EXCLUSIVITY node-partition=
2017-11-12 12:42:14,723 DEBUG org.apache.hadoop.yarn.server.resourcemanager.scheduler.capacity.CapacityScheduler: nodeUpdate: hadoop-worker02:35444 clusterResources: <memory:24576, vCores:24>
2017-11-12 12:42:14,723 DEBUG org.apache.hadoop.yarn.server.resourcemanager.scheduler.capacity.CapacityScheduler: Node being looked for scheduling hadoop-worker02:35444 availableResource: <memory:8192, vCores:8>
2017-11-12 12:42:14,723 DEBUG org.apache.hadoop.yarn.server.resourcemanager.scheduler.capacity.CapacityScheduler: Trying to schedule on node: hadoop-worker02, available: <memory:8192, vCores:8>
2017-11-12 12:42:14,723 DEBUG org.apache.hadoop.yarn.server.resourcemanager.scheduler.capacity.ParentQueue: Skip this queue=root, because it doesn't need more resource, schedulingMode=RESPECT_PARTITION_EXCLUSIVITY node-partition=
2017-11-12 12:42:14,919 DEBUG org.apache.hadoop.yarn.server.resourcemanager.scheduler.capacity.CapacityScheduler: nodeUpdate: hadoop-worker01:41792 clusterResources: <memory:24576, vCores:24>
2017-11-12 12:42:14,919 DEBUG org.apache.hadoop.yarn.server.resourcemanager.scheduler.capacity.CapacityScheduler: Node being looked for scheduling hadoop-worker01:41792 availableResource: <memory:8192, vCores:8>
2017-11-12 12:42:14,919 DEBUG org.apache.hadoop.yarn.server.resourcemanager.scheduler.capacity.CapacityScheduler: Trying to schedule on node: hadoop-worker01, available: <memory:8192, vCores:8>
2017-11-12 12:42:14,919 DEBUG org.apache.hadoop.yarn.server.resourcemanager.scheduler.capacity.ParentQueue: Skip this queue=root, because it doesn't need more resource, schedulingMode=RESPECT_PARTITION_EXCLUSIVITY node-partition=
2017-11-12 12:42:15,344 DEBUG org.apache.hadoop.yarn.server.resourcemanager.scheduler.capacity.CapacityScheduler: nodeUpdate: hadoop-worker03:34047 clusterResources: <memory:24576, vCores:24>
2017-11-12 12:42:15,345 DEBUG org.apache.hadoop.yarn.server.resourcemanager.scheduler.capacity.CapacityScheduler: Node being looked for scheduling hadoop-worker03:34047 availableResource: <memory:8192, vCores:8>
2017-11-12 12:42:15,345 DEBUG org.apache.hadoop.yarn.server.resourcemanager.scheduler.capacity.CapacityScheduler: Trying to schedule on node: hadoop-worker03, available: <memory:8192, vCores:8>
2017-11-12 12:42:15,345 DEBUG org.apache.hadoop.yarn.server.resourcemanager.scheduler.capacity.ParentQueue: Skip this queue=root, because it doesn't need more resource, schedulingMode=RESPECT_PARTITION_EXCLUSIVITY node-partition=
2017-11-12 12:42:15,724 DEBUG org.apache.hadoop.yarn.server.resourcemanager.scheduler.capacity.CapacityScheduler: nodeUpdate: hadoop-worker02:35444 clusterResources: <memory:24576, vCores:24>
2017-11-12 12:42:15,724 DEBUG org.apache.hadoop.yarn.server.resourcemanager.scheduler.capacity.CapacityScheduler: Node being looked for scheduling hadoop-worker02:35444 availableResource: <memory:8192, vCores:8>
2017-11-12 12:42:15,724 DEBUG org.apache.hadoop.yarn.server.resourcemanager.scheduler.capacity.CapacityScheduler: Trying to schedule on node: hadoop-worker02, available: <memory:8192, vCores:8>
2017-11-12 12:42:15,724 DEBUG org.apache.hadoop.yarn.server.resourcemanager.scheduler.capacity.ParentQueue: Skip this queue=root, because it doesn't need more resource, schedulingMode=RESPECT_PARTITION_EXCLUSIVITY node-partition=
2017-11-12 12:42:15,921 DEBUG org.apache.hadoop.yarn.server.resourcemanager.scheduler.capacity.CapacityScheduler: nodeUpdate: hadoop-worker01:41792 clusterResources: <memory:24576, vCores:24>
2017-11-12 12:42:15,921 DEBUG org.apache.hadoop.yarn.server.resourcemanager.scheduler.capacity.CapacityScheduler: Node being looked for scheduling hadoop-worker01:41792 availableResource: <memory:8192, vCores:8>
2017-11-12 12:42:15,921 DEBUG org.apache.hadoop.yarn.server.resourcemanager.scheduler.capacity.CapacityScheduler: Trying to schedule on node: hadoop-worker01, available: <memory:8192, vCores:8>
2017-11-12 12:42:15,921 DEBUG org.apache.hadoop.yarn.server.resourcemanager.scheduler.capacity.ParentQueue: Skip this queue=root, because it doesn't need more resource, schedulingMode=RESPECT_PARTITION_EXCLUSIVITY node-partition=
2017-11-12 12:42:16,347 DEBUG org.apache.hadoop.yarn.server.resourcemanager.scheduler.capacity.CapacityScheduler: nodeUpdate: hadoop-worker03:34047 clusterResources: <memory:24576, vCores:24>
2017-11-12 12:42:16,347 DEBUG org.apache.hadoop.yarn.server.resourcemanager.scheduler.capacity.CapacityScheduler: Node being looked for scheduling hadoop-worker03:34047 availableResource: <memory:8192, vCores:8>
2017-11-12 12:42:16,348 DEBUG org.apache.hadoop.yarn.server.resourcemanager.scheduler.capacity.CapacityScheduler: Trying to schedule on node: hadoop-worker03, available: <memory:8192, vCores:8>
2017-11-12 12:42:16,348 DEBUG org.apache.hadoop.yarn.server.resourcemanager.scheduler.capacity.ParentQueue: Skip this queue=root, because it doesn't need more resource, schedulingMode=RESPECT_PARTITION_EXCLUSIVITY node-partition=
